Workbook

Sheet Sheet1
G5: Hari, tanggal: | H5: Senin, 27 Jul 2026
A6: Kajian Harian Risiko Likuiditas
A7: Pemantauan Ketersediaan Alat Likuid
A8: No | C8: Keterangan | E8: 46226 | G8: 46227
A9: A. | B9: Primary Reserve Rupiah (Juta Rupiah)
B10: 1. | C10: Kas Rupiah (Juta Rupiah) | E10: Normal | G10: Normal
C11: Pagu Kas Rupiah BNI Wide***** | E11: 8303691 | G11: 8303691
C12: Kas Rupiah (Juta Rupiah) | E12: 8528782 | F12: 1.0148735 | G12: 9026825.2 | H12: 1.0397587
C13: Rata-rata realisasi kas rupiah (Periode Normal)**** | E13: 8427196.3 | F13: DARK GREEN | G13: 8633834.9 | H13: DARK GREEN
B14: 2. | C14: Giro Wajib Minimum (GWM) Rupiah
C15: a. GWM Harian (min. 0%) | E15: 0.0634 | F15: 0.0634 | G15: 0.0636 | H15: 0.0636
C16: ▫ R/C BI | E16: 53933292 | G16: 54167675
C17: ▫ DPK | E17: 8.5125517e+08 | G17: 8.5125517e+08
C18: GWM Averaging | E18: 0.050783333 | F18: 0.014783333 | G18: 0.052614286 | H18: 0.016614286
C19: Pemenuhan GWM | E19: 0.036 | G19: 0.036
C20: ▫ Excess Reserve | E20: 23324392 | G20: 23494643
C21: b. GWM Sekunder (PLM) | E21: 0.1890473 | F21: 0.1490473 | G21: 0.18704389 | H21: 0.14704389
C22: ▫ SBI, SDBI, dan SBN | E22: 1.6092749e+08 | G22: 1.5922208e+08
C23: c. Ketentuan
C24: ▫ GWM Rupiah (PADG No. 24/8/PADG/2022 tgl. 30 Juni 2022) | E24: 0.09 | G24: 0.09
C25: ▫ GWM Sekunder - PLM | E25: 0.04 | G25: 0.04
A26: B. | B26: Primary Reserve Valas (Ribu USD)
B27: 1. | C27: Kas Valas (Ribu USD) | E27: 91925.262 | G27: 101194.18
C28: Pagu kas valas BNI Wide | E28: 87230.142 | F28: 1.0936546 | G28: 87230.142 | H28: 1.1162561
C29: Rata-rata realisasi kas valas (5 Hari)**** | E29: 95399.649 | F29: LIGHT YELLOW | G29: 97371.175 | H29: DARK YELLOW
B30: 2. | C30: Giro Wajib Minimum (GWM) Valas
C31: a. GWM Valas | E31: 0.040034887 | F31: 3.4886939e-05 | G31: 0.040034887 | H31: 3.4886939e-05
C32: ▫ R/C BI Valas | E32: 574622 | G32: 574622
C33: ▫ DPK Valas | E33: 14353032 | G33: 14353032
C34: b. Ketentuan (PADG No 22/2/PADG/2020 tgl 13 Maret 2020)
C35: ▫ GWM Valas | E35: 0.04 | G35: 0.04
A36: C. | B36: Safety Level (Juta Rupiah)
B37: 1. | C37: Tight/Normal* | E37: Moderate | G37: Moderate
B38: 2. | C38: Safety Level** | E38: 15500000 | G38: 15500000
B39: 3. | C39: Cadangan Likuiditas | E39: 23000000 | F39: GREEN | G39: 23250000 | H39: GREEN
B40: 4. | C40: TR Liquid (after haircut 20%) | E40: 57763312 | G40: 57731140
B41: 5. | C41: Status Likuiditas***
A42: D. | B42: Safety Level (Ribu USD)
B43: 1. | C43: Tight/Normal* | E43: Moderate | G43: Moderate
B44: 2. | C44: Safety Level** | E44: 1200000 | G44: 1200000
...

Sheet Sheet2
G5: Hari, tanggal: | H5: Kamis, 24 Apr 2025
A6: Kajian Harian Risiko Likuiditas
A7: Pemantauan Ketersediaan Alat Likuid
A8: No | C8: Keterangan | E8: 45769 | G8: 45770
A9: A. | B9: Primary Reserve Rupiah (Juta Rupiah) | M9: =IF(B9=Sheet1!B9,"",1) | N9: =IF(C9=Sheet1!C9,"",1)
B10: 1. | C10: Kas Rupiah (Juta Rupiah) | E10: Normal | G10: Normal | M10: =IF(B10=Sheet1!B10,"",1) | N10: =IF(C10=Sheet1!C10,"",1)
C11: Pagu Kas Rupiah BNI Wide***** | E11: 8666970 | G11: 8666970 | M11: =IF(B11=Sheet1!B11,"",1) | N11: =IF(C11=Sheet1!C11,"",1)
C12: Kas Rupiah (Juta Rupiah) | E12: 9154009.5 | F12: 1.0330729 | G12: 8842957 | H12: 1.0236671 | M12: =IF(B12=Sheet1!B12,"",1) | N12: =IF(C12=Sheet1!C12,"",1)
C13: Rata-rata realisasi kas rupiah (Periode Normal)**** | E13: 8953612.1 | F13: DARK GREEN | G13: 8872092.1 | H13: DARK GREEN | M13: =IF(B13=Sheet1!B13,"",1) | N13: =IF(C13=Sheet1!C13,"",1)
B14: 2. | C14: Giro Wajib Minimum (GWM) Rupiah | M14: =IF(B14=Sheet1!B14,"",1) | N14: =IF(C14=Sheet1!C14,"",1)
C15: a. GWM Harian (min. 0%) | E15: 0.0403 | F15: 0.0403 | G15: 0.0403 | H15: 0.0403 | M15: =IF(B15=Sheet1!B15,"",1) | N15: =IF(C15=Sheet1!C15,"",1)
C16: ▫ R/C BI | E16: 25783542 | G16: 25790670 | M16: =IF(B16=Sheet1!B16,"",1) | N16: =IF(C16=Sheet1!C16,"",1)
C17: ▫ DPK | E17: 6.4056636e+08 | G17: 6.4056636e+08 | M17: =IF(B17=Sheet1!B17,"",1) | N17: =IF(C17=Sheet1!C17,"",1)
C18: GWM Averaging | E18: 0.042125 | F18: 0.002125 | G18: 0.04176 | H18: 0.00176 | M18: =IF(B18=Sheet1!B18,"",1) | N18: =IF(C18=Sheet1!C18,"",1)
C19: Pemenuhan GWM | E19: 0.04 | G19: 0.04 | M19: =IF(B19=Sheet1!B19,"",1) | N19: =IF(C19=Sheet1!C19,"",1)
C20: ▫ Excess Reserve | E20: 192169.91 | G20: 192169.91 | M20: =IF(B20=Sheet1!B20,"",1) | N20: =IF(C20=Sheet1!C20,"",1)
C21: b. GWM Sekunder (PLM) | E21: 0.1761808 | F21: 0.1261808 | G21: 0.18346606 | H21: 0.13346606 | M21: =IF(B21=Sheet1!B21,"",1) | N21: =IF(C21=Sheet1!C21,"",1)
C22: ▫ SBI, SDBI, dan SBN | E22: 1.1285549e+08 | G22: 1.1752219e+08 | M22: =IF(B22=Sheet1!B22,"",1) | N22: =IF(C22=Sheet1!C22,"",1)
C23: c. Ketentuan | M23: =IF(B23=Sheet1!B23,"",1) | N23: =IF(C23=Sheet1!C23,"",1)
C24: ▫ GWM Rupiah (PADG No. 24/8/PADG/2022 tgl. 30 Juni 2022) | E24: 0.09 | G24: 0.09 | M24: =IF(B24=Sheet1!B24,"",1) | N24: =IF(C24=Sheet1!C24,"",1)
C25: ▫ GWM Sekunder - PLM | E25: 0.05 | G25: 0.05 | M25: =IF(B25=Sheet1!B25,"",1) | N25: =IF(C25=Sheet1!C25,"",1)
A26: B. | B26: Primary Reserve Valas (Ribu USD) | M26: =IF(B26=Sheet1!B26,"",1) | N26: =IF(C26=Sheet1!C26,"",1)
B27: 1. | C27: Kas Valas (Ribu USD) | E27: 71412.78 | G27: 70747.339 | M27: =IF(B27=Sheet1!B27,"",1) | N27: =IF(C27=Sheet1!C27,"",1)
C28: Pagu kas valas BNI Wide | E28: 76529.68 | F28: 0.94630547 | G28: 76529.68 | H28: 0.94070262 | M28: =IF(B28=Sheet1!B28,"",1) | N28: =IF(C28=Sheet1!C28,"",1)
C29: Rata-rata realisasi kas valas (5 Hari)**** | E29: 72420.455 | F29: DARK GREEN | G29: 71991.67 | H29: DARK GREEN | M29: =IF(B29=Sheet1!B29,"",1) | N29: =IF(C29=Sheet1!C29,"",1)
B30: 2. | C30: Giro Wajib Minimum (GWM) Valas | M30: =IF(B30=Sheet1!B30,"",1) | N30: =IF(C30=Sheet1!C30,"",1)
C31: a. GWM Valas | E31: 0.040028092 | F31: 2.80916e-05 | G31: 0.040028092 | H31: 2.80916e-05 | M31: =IF(B31=Sheet1!B31,"",1) | N31: =IF(C31=Sheet1!C31,"",1)
C32: ▫ R/C BI Valas | E32: 507750 | G32: 507750 | M32: =IF(B32=Sheet1!B32,"",1) | N32: =IF(C32=Sheet1!C32,"",1)
C33: ▫ DPK Valas | E33: 12684842 | G33: 12684842 | M33: =IF(B33=Sheet1!B33,"",1) | N33: =IF(C33=Sheet1!C33,"",1)
C34: b. Ketentuan (PADG No 22/2/PADG/2020 tgl 13 Maret 2020) | M34: =IF(B34=Sheet1!B34,"",1) | N34: =IF(C34=Sheet1!C34,"",1)
C35: ▫ GWM Valas | E35: 0.04 | G35: 0.04 | M35: =IF(B35=Sheet1!B35,"",1) | N35: =IF(C35=Sheet1!C35,"",1)
A36: C. | B36: Safety Level - Adjusted SR Ideal Rupiah (Juta Rupiah) | M36: =IF(B36=Sheet1!B36,"",1) -> 1 | N36: =IF(C36=Sheet1!C36,"",1)
B37: 1. | C37: Tight/Normal* | E37: Normal | G37: Normal | M37: =IF(B37=Sheet1!B37,"",1) | N37: =IF(C37=Sheet1!C37,"",1)
B38: 2. | C38: Safety Level (Adjusted SR Ideal)** | E38: 13800000 | G38: 13800000 | M38: =IF(B38=Sheet1!B38,"",1) | N38: =IF(C38=Sheet1!C38,"",1) -> 1
B39: 3. | C39: Cadangan Likuiditas (Adjusted SR Netto) | E39: 14913000 | F39: GREEN | G39: 15040000 | H39: GREEN | M39: =IF(B39=Sheet1!B39,"",1) | N39: =IF(C39=Sheet1!C39,"",1) -> 1
B40: 4. | C40: TR Liquid (after haircut 20%) | E40: 47684089 | G40: 47753440 | M40: =IF(B40=Sheet1!B40,"",1) | N40: =IF(C40=Sheet1!C40,"",1)
B41: 5. | C41: Status Likuiditas*** | M41: =IF(B41=Sheet1!B41,"",1) | N41: =IF(C41=Sheet1!C41,"",1)
A42: D. | B42: Safety Level - Adjusted SR Ideal Valas (Ribu USD) | M42: =IF(B42=Sheet1!B42,"",1) -> 1 | N42: =IF(C42=Sheet1!C42,"",1)
B43: 1. | C43: Tight/Normal* | E43: Normal | G43: Normal | M43: =IF(B43=Sheet1!B43,"",1) | N43: =IF(C43=Sheet1!C43,"",1)
B44: 2. | C44: Safety Level (Adjusted SR Ideal)** | E44: 1000000 | G44: 1000000 | M44: =IF(B44=Sheet1!B44,"",1) | N44: =IF(C44=Sheet1!C44,"",1) -> 1
...

Sheet upload
A1: No | C1: Keterangan | E1: 46227
A2: A. | B2: Primary Reserve Rupiah (Juta Rupiah)
B3: 1. | C3: Kas Rupiah (Juta Rupiah) | E3: Normal
C4: Pagu Kas Rupiah BNI Wide***** | E4: 8303691
C5: Kas Rupiah (Juta Rupiah) | E5: 9026825.2 | F5: 1.0397587
C6: Rata-rata realisasi kas rupiah (Periode Normal)**** | E6: 8633834.9 | F6: DARK GREEN
B7: 2. | C7: Giro Wajib Minimum (GWM) Rupiah
C8: a. GWM Harian (min. 0%) | E8: 0.0636 | F8: 0.0636
C9: ▫ R/C BI | E9: 54167675
C10: ▫ DPK | E10: 8.5125517e+08
C11: GWM Averaging | E11: 0.052614286 | F11: 0.016614286
C12: Pemenuhan GWM | E12: 0.036
C13: ▫ Excess Reserve | E13: 23494643
C14: b. GWM Sekunder (PLM) | E14: 0.18704389 | F14: 0.14704389
C15: ▫ SBI, SDBI, dan SBN | E15: 1.5922208e+08
C16: c. Ketentuan
C17: ▫ GWM Rupiah (PADG No. 24/8/PADG/2022 tgl. 30 Juni 2022) | E17: 0.09
C18: ▫ GWM Sekunder - PLM | E18: 0.04
A19: B. | B19: Primary Reserve Valas (Ribu USD)
B20: 1. | C20: Kas Valas (Ribu USD) | E20: 101194.18
C21: Pagu kas valas BNI Wide | E21: 87230.142 | F21: 1.1162561
C22: Rata-rata realisasi kas valas (5 Hari)**** | E22: 97371.175 | F22: DARK YELLOW
B23: 2. | C23: Giro Wajib Minimum (GWM) Valas
C24: a. GWM Valas | E24: 0.040034887 | F24: 3.4886939e-05
C25: ▫ R/C BI Valas | E25: 574622
C26: ▫ DPK Valas | E26: 14353032
C27: b. Ketentuan (PADG No 22/2/PADG/2020 tgl 13 Maret 2020)
C28: ▫ GWM Valas | E28: 0.04
A29: C. | B29: Safety Level (Juta Rupiah)
B30: 1. | C30: Tight/Normal* | E30: Moderate
B31: 2. | C31: Safety Level** | E31: 15500000
B32: 3. | C32: Cadangan Likuiditas | E32: 23250000 | F32: GREEN
B33: 4. | C33: TR Liquid (after haircut 20%) | E33: 57731140
B34: 5. | C34: Status Likuiditas***
A35: D. | B35: Safety Level (Ribu USD)
B36: 1. | C36: Tight/Normal* | E36: Moderate
B37: 2. | C37: Safety Level** | E37: 1200000
B38: 3. | C38: Cadangan Likuiditas | E38: 2520000 | F38: GREEN
B39: 4. | C39: TR Liquid (after haircut 20%) | E39: 373584.98
A41: E. | B41: Rasio Intermediasi Makroprudensial (RIM) (Juta Rupiah) ******
...
