Workbook
Name RATE: '[1]Otomasi adjst'!$C$2

Sheet 2026
A1: DAFTAR RINCIAN
A2: 1. Profil Maturitas
F3: dalam Ribuan USD
A4: 46203 | B4: Aset | C4: Kewajiban | D4: Selisih | E4: Profil Maturitas | F4: Reserve Requirement | G4: Traffic Light
A5: Hongkong | B5: =HK!J6 -> 666419 | C5: =HK!J7 -> 281066 | D5: =B5-C5 -> 385353 | E5: =B5/C5 -> 2.371041 | F5: OK | G5: =IF(E5>100%,"Green",IF(E5>70%,"Yellow","Red")) -> Green | H5: = | I5: =B5-B19 -> 86914 | J5: =C5-C19 -> 34390 | M5: =E5-E19 -> 0.021785262
A6: London | B6: =LDN!J8 -> 88446 | C6: =LDN!J9 -> 64768 | D6: =B6-C6 -> 23678 | E6: =B6/C6 -> 1.3655818 | F6: OK | G6: =IF(E6>100%,"Green",IF(E6>70%,"Yellow","Red")) -> Green | H6: = | I6: =B6-B20 -> 3613 | J6: =C6-C20 -> 24043 | M6: =E6-E20 -> -0.7174876
A7: New York | B7: =NY!J9 -> 1444597.6 | C7: =NY!J8 -> 1318744.6 | D7: =B7-C7 -> 125853 | E7: =B7/C7 -> 1.0954339 | F7: OK | G7: =IF(E7>100%,"Green",IF(E7>70%,"Yellow","Red")) -> Green | H7: = | I7: =B7-B21 -> 1041978.8 | J7: =C7-C21 -> 1032114.8 | M7: =E7-E21 -> -0.30923086
A8: Seoul | B8: =SEO!K8 -> 37739 | C8: =SEO!K9 -> 2527 | D8: =B8-C8 -> 35212 | E8: =B8/C8 -> 14.934309 | F8: OK | G8: =IF(E8>100%,"Green",IF(E8>70%,"Yellow","Red")) -> Green | H8: = | I8: =B8-B22 -> 12683 | J8: =C8-C22 -> -13 | M8: =E8-E22 -> 5.0697425
A9: Singapore | B9: =SG!N8 -> 490287 | C9: =SG!N9 -> 431818 | D9: =B9-C9 -> 58469 | E9: =B9/C9 -> 1.135402 | F9: OK | G9: =IF(E9>100%,"Green",IF(E9>70%,"Yellow","Red")) -> Green | H9: = | I9: =B9-B23 -> -99751 | J9: =C9-C23 -> 71714 | M9: =E9-E23 -> -0.50311914
A10: Tokyo | B10: =TKY!J7 -> 596768 | C10: =TKY!J8 -> 476706 | D10: =B10-C10 -> 120062 | E10: =B10/C10 -> 1.2518575 | F10: OK | G10: =IF(E10>100%,"Green",IF(E10>70%,"Yellow","Red")) -> Green | H10: = | I10: =B10-B24 -> -55305 | J10: =C10-C24 -> -43622 | M10: =E10-E24 -> -0.0013385219
A15: DAFTAR RINCIAN
A16: 1. Profil Maturitas
B17: =B6-B20 -> 3613 | C17: =C6-C20 -> 24043 | F17: dalam Ribuan USD
A18: 46173 | B18: Aset | C18: Kewajiban | D18: Selisih | E18: Profil Maturitas | F18: Reserve Requirement | G18: Traffic Light
A19: Hongkong | B19: 579505 | C19: 246676 | D19: 332829 | E19: 2.3492557 | F19: OK | G19: Green
A20: London | B20: 84833 | C20: 40725 | D20: 44108 | E20: 2.0830694 | F20: OK | G20: Green
A21: New York | B21: 402618.82 | C21: 286629.82 | D21: 115989 | E21: 1.4046648 | F21: OK | G21: Green
A22: Seoul | B22: 25056 | C22: 2540 | D22: 22516 | E22: 9.8645669 | F22: OK | G22: Green
A23: Singapore | B23: 590038 | C23: 360104 | D23: 229934 | E23: 1.6385211 | F23: OK | G23: Green
A24: Tokyo | B24: 652073 | C24: 520328 | D24: 131745 | E24: 1.2531961 | F24: OK | G24: Green

Sheet upload
A1: 46203 | B1: Aset | C1: Kewajiban | D1: Selisih | E1: Profil Maturitas | F1: Reserve Requirement | G1: Traffic Light
A2: Hongkong | B2: 666419 | C2: 281066 | D2: 385353 | E2: 2.371041 | F2: OK | G2: Green
A3: London | B3: 88446 | C3: 64768 | D3: 23678 | E3: 1.3655818 | F3: OK | G3: Green
A4: New York | B4: 1444597.6 | C4: 1318744.6 | D4: 125853 | E4: 1.0954339 | F4: OK | G4: Green
A5: Seoul | B5: 37739 | C5: 2527 | D5: 35212 | E5: 14.934309 | F5: OK | G5: Green
A6: Singapore | B6: 490287 | C6: 431818 | D6: 58469 | E6: 1.135402 | F6: OK | G6: Green
A7: Tokyo | B7: 596768 | C7: 476706 | D7: 120062 | E7: 1.2518575 | F7: OK | G7: Green

Sheet Sheet3

Sheet HK
A2: A | B2: B | C2: C | D2: D | E2: E | F2: F | G2: G | J2: H | K2: I | L2: J | M2: K | N2: L | O2: M | P2: N | AA2: Q | AB2: R | AC2: S
B4: LAPORAN PROFIL MATURITAS
B5: Periode 30 Jun 2026 | J5: Periode 31 Maret 2012
B6: (All) | J6: =SUM(K31:M31)+SUM(K67:M67) -> 666419 | L6: =J6-J7 -> 385353
J7: =+SUM(K54:M54)+SUM(K78:M78) -> 281066
N8: (ekuivalen dalam ribuan USD)
B9: Pos-Pos | J9: Balance | N9: Jatuh Tempo*) | AA9: Unit in Charge | AC9: Keterangan
H10: Items | I10: Mapping | K10: s.d 1 minggu | L10: > 1 minggu s.d 2 minggu | M10: > 2 minggu s.d. 1 bulan | N10: > 1 bln s.d 3 bln | O10: > 3 bln s.d 6 bln | P10: > 6 bln s.d 12 bln | Q10: > 1 y to 2 y | R10: > 2 y to 3 y | S10: > 3 y to 4 y | T10: > 4 y to 5 y | U10: > 5 y to 7 y | V10: > 7 y to 10 y | W10: > 10 y to 15 y | X10: > 15 y to 20 y | Y10: > 20 y | Z10: AC Balance Not Included
B12: I. | C12: NERACA
B13: A. | C13: Aset
C14: 1. | D14: Kas | H14: 1. Cash on hand | I14: AC 100001 | J14: 313 | K14: 312.99943 | L14: 0 | M14: 0 | N14: 0 | O14: 0 | P14: 0 | Q14: 0 | R14: 0 | S14: 0 | T14: 0 | U14: 0 | V14: 0 | W14: 0 | X14: 0 | Y14: 0 | AA14: BAM (TRS) | AB14: NY, LDN, SGP, HKG, TKO branch | AC14: cukup jelas
C15: 2. | D15: Penempatan pada Bank Indonesia | H15: 2. Nostro & Placement in Bank Indonesia | I15: N.A. | J15: 0 | K15: 0 | L15: 0 | M15: 0 | N15: 0 | O15: 0 | P15: 0 | Q15: 0 | R15: 0 | S15: 0 | T15: 0 | U15: 0 | V15: 0 | W15: 0 | X15: 0 | Y15: 0 | AA15: BAM (TRS) | AB15: NY, LDN, SGP, HKG, TKO branch | AC15: cukup jelas
C16: 3. | D16: Penempatan pada bank lain | H16: 3. Nostro & Placement in Other Banks | I16: AC 102001DR + 102002DR + 210001DR + 110101 + 110103 | J16: 190127 | K16: 190126.52 | L16: 0 | M16: 0 | N16: 0 | O16: 0 | P16: 0 | Q16: 0 | R16: 0 | S16: 0 | T16: 0 | U16: 0 | V16: 0 | W16: 0 | X16: 0 | Y16: 0 | AA16: BAM (TRS) | AB16: NY, LDN, SGP, HKG, TKO branch | AC16: cukup jelas
C17: 4. | D17: Surat Berharga **) | H17: 4. Securities | I17: 4. Securities
D18: a. | E18: Surat berharga korporasi | H18: a. Corporate & Bank Securities
E19: 1) | F19: diperdagangkan | H19: (1) Trading | J19: 0 | K19: 0 | L19: 0 | M19: 0 | N19: 0 | O19: 0 | P19: 0 | Q19: 0 | R19: 0 | S19: 0 | T19: 0 | U19: 0 | V19: 0 | W19: 0 | X19: 0 | Y19: 0 | AA19: BAM (TRS) | AB19: NY, LDN, SGP, HKG, TKO branch | AC19: cukup jelas
E20: 2) | F20: tersedia untuk dijual | H20: (2) AFS | J20: 0 | K20: 0 | L20: 0 | M20: 0 | N20: 0 | O20: 0 | P20: 0 | Q20: 0 | R20: 0 | S20: 0 | T20: 0 | U20: 0 | V20: 0 | W20: 0 | X20: 0 | Y20: 0 | AA20: BAM (TRS) | AB20: NY, LDN, SGP, HKG, TKO branch | AC20: cukup jelas
E21: 3) | F21: dimiliki hingga jatuh tempo | H21: (3) Held-to-Maturity | I21: N.A | J21: 0 | K21: 0 | L21: 0 | M21: 0 | N21: 0 | O21: 0 | P21: 0 | AA21: BAM (TRS) | AB21: NY, LDN, SGP, HKG, TKO branch | AC21: cukup jelas
E22: 4) | F22: pinjaman yang diberikan dan piutang | H22: (4) Loans and Receviables | I22: N.A | J22: 0 | K22: 0 | L22: 0 | M22: 0 | N22: 0 | O22: 0 | P22: 0 | AA22: BAM (TRS) | AB22: NY, LDN, SGP, HKG, TKO branch | AC22: cukup jelas
D23: b. | E23: Lainnya | H23: b. Gov & Other Securities | I23: AC 115127 + 115135 + 115136 + 115183 + 115147 +115155 +115182 + 115181 + 171101 + 179105 (Gov sec only) | J23: 143063 | K23: 0 | L23: 0 | M23: 0 | N23: 0 | O23: 0 | P23: 42564.536 | Q23: 26913.556 | R23: 6504.2806 | S23: 2837.8657 | T23: 29410.866 | U23: 34832.327 | V23: 0 | W23: 0 | X23: 0 | Y23: 0 | AA23: BAM (TRS) | AB23: NY, LDN, SGP, HKG, TKO branch | AC23: Surat Berharga yang tidak dapat dimasukkan atau digolongkan ke dalam salah satu dari huruf a dan huruf b.
C24: 5. | D24: Kredit Yang Diberikan | H24: 5. Loans (Include trade finance loans) | I24: 5. Loans (Include trade finance loans) | V24: 0
D25: a. | E25: belum jatuh tempo | H25: a. Current | I25: AC 140001 + 140003 + 140005 + 140011 | J25: 1007623 | K25: 15938.591 | L25: 7532.7609 | M25: 12508.291 | N25: 7433.6434 | O25: 33930.359 | P25: 25100 | Q25: 0 | R25: 353427.21 | S25: 370071.67 | T25: 105972.16 | U25: 9250 | V25: 66457.995 | W25: 0 | X25: 0 | Y25: 0 | AA25: BAM (TRS) | AB25: NY, LDN, SGP, HKG, TKO branch | AC25: diisi sesuai jumlah kredit yang belum jatuh tempo berdasarkan kontrak
D26: b. | E26: sudah jatuh tempo ***) | H26: b. Overdue | I26: Input based on the scheduled repayment agreed by the debtors | J26: 0 | K26: 0 | L26: 0 | M26: 0 | N26: 0 | O26: 0 | P26: 0 | Q26: 0 | R26: 0 | S26: 0 | T26: 0 | U26: 0 | V26: 0 | W26: 0 | X26: 0 | Y26: 0 | Z26: 0 | AA26: BAM (TRS) | AB26: NY, LDN, SGP, HKG, TKO branch | AC26: diisi berdasarkan perkiraan diperolehnya pembayaran atas kredit yang berdasarkan kontrak sudah jatuh tempo.
C27: 6. | D27: Tagihan lainnya | H27: 6. Other Receivables | I27: 6. Other Receivables
D28: a. | E28: Tagihan atas Surat Berharga yang dibeli dengan janji dijual kembali (Reverse Repo) | H28: a. Reverse Repos | I28: N.A. | J28: 0 | K28: 0 | L28: 0 | M28: 0 | N28: 0 | O28: 0 | P28: 0 | Q28: 0 | R28: 0 | S28: 0 | T28: 0 | U28: 0 | V28: 0 | W28: 0 | X28: 0 | Y28: 0 | AA28: BAM (TRS) | AB28: NY, LDN, SGP, HKG, TKO branch | AC28: cukup jelas
D29: b. | E29: Lainnya | H29: b. Others (Bills Receivables + Cash In Transit) | I29: AC 120001 + 150004 + 100002 | J29: 426 | K29: 0 | L29: 0 | M29: 0 | N29: 0 | O29: 425.83939 | P29: 0 | Q29: 0 | R29: 0 | S29: 0 | T29: 0 | U29: 0 | V29: 0 | W29: 0 | X29: 0 | Y29: 0 | AA29: BAM (TRS) | AB29: NY, LDN, SGP, HKG, TKO branch | AC29: Tagihan lainnya yang tidak dapat dimasukkan atau digolongkan ke dalam salah satu dari huruf a.
C30: 7. | D30: Lain-lain (Account Balance not included) For reconciliation purpose | J30: 44586.671 | Z30: 44586.671 | AA30: BAM (TRS) | AB30: NY, LDN, SGP, HKG, TKO branch | AC30: Asset yang tidak dapat dimasukkan atau digolongkan ke dalam salah satu dari pos 1 s.d. 6
B31: Total Aset | J31: 1386138.7 | K31: 206378 | L31: 7533 | M31: 12508 | N31: 7434 | O31: 34356 | P31: 67665 | Q31: 26914 | R31: 359931 | S31: 372910 | T31: 135383 | U31: 44082 | V31: 66458 | W31: 0 | X31: 0 | Y31: 0 | Z31: 44587
B33: B. | C33: Kewajiban
C34: 1. | D34: Dana Pihak Ketiga | H34: 1. Customer Deposits
D35: a. | E35: Giro | H35: a. Current Accounts | I35: AC 210001(except Bank) | J35: 57262 | K35: 57261.74 | L35: 0 | M35: 0 | N35: 0 | O35: 0 | P35: 0 | Q35: 0 | R35: 0 | S35: 0 | T35: 0 | U35: 0 | V35: 0 | W35: 0 | X35: 0 | Y35: 0 | AA35: BAM (TRS) | AB35: NY, LDN, SGP, HKG, TKO branch | AC35: cukup jelas
D36: b. | E36: Tabungan | H36: b. Savings Accounts | I36: AC 210011 | J36: 25 | K36: 25.353444 | L36: 0 | M36: 0 | N36: 0 | O36: 0 | P36: 0 | Q36: 0 | R36: 0 | S36: 0 | T36: 0 | U36: 0 | V36: 0 | W36: 0 | X36: 0 | Y36: 0 | AA36: BAM (TRS) | AB36: NY, LDN, SGP, HKG, TKO branch | AC36: cukup jelas
D37: c. | E37: Simpanan Berjangka | H37: c. Time Deposits
E38: 1) | F38: Deposit on call | H38: (1) Deposit at notice | I38: N.A. | J38: 0 | K38: 0 | L38: 0 | M38: 0 | N38: 0 | O38: 0 | P38: 0 | Q38: 0 | R38: 0 | S38: 0 | T38: 0 | U38: 0 | V38: 0 | W38: 0 | X38: 0 | Y38: 0 | AA38: BAM (TRS) | AB38: NY, LDN, SGP, HKG, TKO branch | AC38: cukup jelas
E39: 2) | F39: Deposito berjangka | H39: (2) Time Deposits | I39: AC 210031 | J39: 29058 | K39: 166.94231 | L39: 7450 | M39: 3022.9096 | N39: 18371.622 | O39: 46.68597 | P39: 0 | Q39: 0 | R39: 0 | S39: 0 | T39: 0 | U39: 0 | V39: 0 | W39: 0 | X39: 0 | Y39: 0 | AA39: BAM (TRS) | AB39: NY, LDN, SGP, HKG, TKO branch | AC39: cukup jelas
E40: 3) | F40: Lainnya | H40: (3) Others | I40: N.A. | J40: 0 | K40: 0 | L40: 0 | M40: 0 | N40: 0 | O40: 0 | P40: 0 | Q40: 0 | R40: 0 | S40: 0 | T40: 0 | U40: 0 | V40: 0 | W40: 0 | X40: 0 | Y40: 0 | AA40: BAM (TRS) | AB40: NY, LDN, SGP, HKG, TKO branch | AC40: Simpanan Berjangka yang tidak dapat dimasukkan atau digolongkan ke dalam salah satu dari angka 1) dan angka 2)
C41: 2. | D41: Kewajiban kepada Bank Indonesia | H41: 2. Laibilities to Bank Indonesia | I41: AC 210001 | J41: 135 | K41: 134.86637 | L41: 0 | M41: 0 | N41: 0 | O41: 0 | P41: 0 | Q41: 0 | R41: 0 | S41: 0 | T41: 0 | U41: 0 | V41: 0 | W41: 0 | X41: 0 | Y41: 0 | AA41: BAM (TRS) | AB41: NY, LDN, SGP, HKG, TKO branch | AC41: cukup jelas
C42: 3. | D42: Kewajiban kepada bank lain | H42: 3. Laibilities to Other Banks | I42: AC 102001 CR + 210001CR + 2100006CR + 252001 + 252002 + 253001 | J42: 1255775 | K42: 92087.996 | L42: 0 | M42: 0 | N42: 0 | O42: 492000 | P42: 444825.26 | Q42: 46861.35 | R42: 0 | S42: 0 | T42: 150000 | U42: 0 | V42: 0 | W42: 0 | X42: 0 | Y42: 30000 | AA42: BAM (TRS) | AB42: NY, LDN, SGP, HKG, TKO branch | AC42: cukup jelas
C43: 4. | D43: Surat Berharga yang Diterbitkan | H43: 4. Securities Issued
D44: a. | E44: Obligasi | H44: a. Debts | I44: N.A. | J44: 0 | K44: 0 | L44: 0 | M44: 0 | N44: 0 | O44: 0 | P44: 0 | Q44: 0 | R44: 0 | S44: 0 | T44: 0 | U44: 0 | V44: 0 | W44: 0 | X44: 0 | Y44: 0 | AA44: BAM (TRS) | AB44: NY, LDN, SGP, HKG, TKO branch | AC44: cukup jelas
...

Sheet LDN
A2: A | B2: B | C2: C | D2: D | E2: E | F2: F | G2: G | I2: H | J2: I | K2: J | L2: K | M2: L | N2: M | O2: N
B3: Formulir 4.b.
B4: MATURITY PROFILE REPORT - BNI LONDON Branch
B5: CONTRACTUAL BASED
B6: 46203
B7: Valuta Asing
I8: Aset | J8: =SUM(J14:L14)+SUM(J59:L59) -> 88446 | K8: =J8-J9 -> 23678
I9: Kewajiban | J9: =SUM(J68:L68)+SUM(J34:L34) -> 64768 | L9: =I14-I34 -> 0 | W9: in Thousand USD
B10: Pos-Pos | H10: Sandi | I10: Saldo | J10: Time to Maturity *)
J11: up to 1 week | K11: > 1 week to 2 weeks | L11: > 2 weeks to 1 month | M11: > 1 month to 3 months | N11: > 3 months to 6 months | O11: > 6 months to 1 year | P11: > 1 y to 2 y | Q11: > 2 y to 3 y | R11: > 3 y to 4 y | S11: > 4 y to 5 y | T11: > 5 y to 7 y | U11: > 7 y to 10 y | V11: > 10 y to 15 y | W11: > 15 y to 20 y | X11: > 20 y
B13: I. | C13: NERACA
B14: A. | C14: Aset | H14: 10000 | I14: =ROUND(SUM(J14:X14),0) -> 1189497 | J14: =ROUND(+J15+J16+J17+J18+J25+J28+J31,0) -> 88446 | K14: =ROUND(+K15+K16+K17+K18+K25+K28+K31,0) -> 0 | L14: =ROUND(+L15+L16+L17+L18+L25+L28+L31,0) -> 0 | M14: =ROUND(+M15+M16+M17+M18+M25+M28+M31,0) -> 8822 | N14: =ROUND(+N15+N16+N17+N18+N25+N28+N31,0) -> 19868 | O14: =ROUND(+O15+O16+O17+O18+O25+O28+O31,0) -> 31717 | P14: =ROUND(+P15+P16+P17+P18+P25+P28+P31,0) -> 16131 | Q14: =ROUND(+Q15+Q16+Q17+Q18+Q25+Q28+Q31,0) -> 207724 | ... X14: =ROUND(+X15+X16+X17+X18+X25+X28+X31,0) -> 0
C15: 1. | D15: Kas | H15: 10100 | I15: =ROUND(SUM(J15:X15),0) -> 22 | J15: 21.66859
C16: 2. | D16: Penempatan pada Bank Indonesia | H16: 10200 | I16: =ROUND(SUM(J16:X16),0) -> 0 | X16: =X17*$Z$17 -> 0
C17: 3. | D17: Penempatan pada bank lain | H17: 10300 | I17: =ROUND(SUM(J17:X17),0) -> 160636 | J17: 45178.975 | K17: 0 | L17: 0 | M17: 0 | N17: 0 | O17: 0 | P17: 0 | Q17: 0 | R17: 0 | S17: 115457.38 | T17: 0 | U17: 0 | V17: 0 | W17: 0 | X17: 0
C18: 4. | D18: Surat Berharga **) | H18: 10400 | I18: =ROUND(SUM(J18:X18),0) -> 96848 | J18: =+J19+J24 -> 0 | K18: =+K19+K24 -> 0 | L18: =+L19+L24 -> 0 | M18: =+M19+M24 -> 0 | N18: =+N19+N24 -> 0 | O18: =+O19+O24 -> 3881.9415 | P18: =+P19+P24 -> 7689.7319 | Q18: =+Q19+Q24 -> 0 | ... X18: =+X19+X24 -> 0
D19: a. | E19: Surat berharga korporasi | H19: 10420 | I19: =ROUND(SUM(J19:X19),0) -> 96848 | J19: =+SUM(J20:J23) -> 0 | K19: =+SUM(K20:K23) -> 0 | L19: =+SUM(L20:L23) -> 0 | M19: =+SUM(M20:M23) -> 0 | N19: =+SUM(N20:N23) -> 0 | O19: =+SUM(O20:O23) -> 3881.9415 | P19: =+SUM(P20:P23) -> 7689.7319 | Q19: =+SUM(Q20:Q23) -> 0 | ... S19: =+SUM(S20:S23) -> 2835.2364 | T19: =+SUM(T20:T22) -> 61260.351 | U19: =+SUM(U20:U23) -> 21181.087 | V19: =+SUM(V20:V23) -> 0 | W19: =+SUM(W20:W23) -> 0 | X19: =+SUM(X20:X23) -> 0
E20: 1) | F20: diperdagangkan | H20: 10421 | I20: =ROUND(SUM(J20:X20),0) -> 0 | J20: =J21*$Z$21 -> 0 | K20: =K21*$Z$21 -> 0 | L20: =L21*$Z$21 -> 0 | M20: =M21*$Z$21 -> 0 | N20: =N21*$Z$21 -> 0 | W20: =W21/1000 -> 0 | X20: =X21/1000 -> 0
E21: 2) | F21: tersedia untuk dijual | H21: 10422 | I21: =ROUND(SUM(J21:X21),0) -> 78737 | J21: 0 | K21: 0 | L21: 0 | M21: 0 | N21: 0 | O21: 1883.193 | P21: 7689.7319 | Q21: 0 | R21: 0 | S21: 2835.2364 | T21: 60260.12 | U21: 6068.7034 | V21: 0 | W21: 0 | X21: 0
E22: 3) | F22: dimiliki hingga jatuh tempo | H22: 10423 | I22: =ROUND(SUM(J22:X22),0) -> 18111 | J22: 0 | K22: 0 | L22: 0 | M22: 0 | N22: 0 | O22: 1998.7485 | P22: 0 | Q22: 0 | R22: 0 | S22: 0 | T22: 1000.231 | U22: 15112.384 | V22: 0 | W22: 0 | X22: 0
E23: 4) | F23: pinjaman yang diberikan dan piutang | H23: 10424 | I23: =ROUND(SUM(J23:X23),0) -> 0 | W23: =W22/1000 -> 0
D24: b. | E24: Lainnya | H24: 10490 | I24: =ROUND(SUM(J24:X24),0) -> 0
C25: 5. | D25: Kredit Yang Diberikan | H25: 10500 | I25: =ROUND(SUM(J25:X25),0) -> 888790 | J25: =+SUM(J26:J27) -> 45.180168 | K25: =+SUM(K26:K27) -> 0 | L25: =+SUM(L26:L27) -> 0 | M25: =+SUM(M26:M27) -> 8821.6561 | N25: =+SUM(N26:N27) -> 19867.907 | O25: =+SUM(O26:O27) -> 27835.24 | P25: =+SUM(P26:P27) -> 8440.7886 | Q25: =+SUM(Q26:Q27) -> 207723.6 | ... X25: =+SUM(X26:X27) -> 0
D26: a. | E26: belum jatuh tempo | H26: 10510 | I26: =ROUND(SUM(J26:X26),0) -> 888790 | J26: 45.180168 | K26: 0 | L26: 0 | M26: 8821.6561 | N26: 19867.907 | O26: 27835.24 | P26: 8440.7886 | Q26: 207723.6 | R26: 455780.4 | S26: 30413.419 | T26: 44958.888 | U26: 84903.311 | V26: 0 | W26: 0
D27: b. | E27: sudah jatuh tempo ***) | H27: 10520 | I27: =ROUND(SUM(J27:X27),0) -> 0 | Z27: 0 | AA27: 0 | AB27: 0 | AC27: 0
C28: 6. | D28: Tagihan lainnya | H28: 10700 | I28: =ROUND(SUM(J28:X28),0) -> 0 | J28: =+SUM(J29:J30) -> 0 | K28: =+SUM(K29:K30) -> 0 | L28: =+SUM(L29:L30) -> 0 | M28: =+SUM(M29:M30) -> 0 | N28: =+SUM(N29:N30) -> 0 | O28: =+SUM(O29:O30) -> 0 | P28: =+SUM(P29:P30) -> 0 | Q28: =+SUM(Q29:Q30) -> 0 | ... X28: =+SUM(X29:X30) -> 0
D29: a. | E29: Tagihan atas Surat Berharga yang dibeli dengan janji dijual kembali (Reverse Repo) | H29: 10710 | I29: =ROUND(SUM(J29:X29),0) -> 0 | R29: 0 | S29: 0 | T29: 0 | U29: 0 | V29: 0 | W29: 0 | X29: 0
D30: b. | E30: Lainnya | H30: 10790 | I30: =ROUND(SUM(J30:X30),0) -> 0 | S30: 0 | T30: 0 | U30: 0 | V30: 0 | W30: 0 | X30: 0
C31: 7. | D31: Lain-lain | H31: 10600 | I31: =ROUND(SUM(J31:X31),0) -> 43200 | J31: 43200.245 | N31: 0 | O31: 0 | P31: 0 | Q31: 0 | R31: 0 | S31: 0 | T31: 0 | U31: 0 | V31: 0 | W31: 0 | X31: 0
B34: B. | C34: Kewajiban | H34: 20000 | I34: =ROUND(SUM(J34:X34),0) -> 1189497 | J34: =ROUND(+J35+J42+J43+J44+J48+J51+J54,0) -> 36097 | K34: =ROUND(+K35+K42+K43+K44+K48+K51+K54,0) -> 0 | L34: =ROUND(+L35+L42+L43+L44+L48+L51+L54,0) -> 28671 | M34: =ROUND(+M35+M42+M43+M44+M48+M51+M54,0) -> 197320 | N34: =ROUND(+N35+N42+N43+N44+N48+N51+N54,0) -> 356505 | O34: =ROUND(+O35+O42+O43+O44+O48+O51+O54,0) -> 27739 | P34: =ROUND(+P35+P42+P43+P44+P48+P51+P54,0) -> 167996 | Q34: =ROUND(+Q35+Q42+Q43+Q44+Q48+Q51+Q54,0) -> 0 | ... X34: =ROUND(+X35+X42+X43+X44+X48+X51+X54,0) -> 30000
C35: 1. | D35: Dana Pihak Ketiga | H35: 20100 | I35: =ROUND(SUM(J35:X35),0) -> 193801 | J35: =+J36+J37+J38 -> 36097.286 | K35: =+K36+K37+K38 -> 0 | L35: =+L36+L37+L38 -> 0 | M35: =+M36+M37+M38 -> 742.31957 | N35: =+N36+N37+N38 -> 52592.767 | O35: =+O36+O37+O38 -> 0 | P35: =+P36+P37+P38 -> 104368.45 | Q35: =+Q36+Q37+Q38 -> 0 | ... X35: =+X36+X37+X38 -> 0
D36: a. | E36: Giro | H36: 20110 | I36: =ROUND(SUM(J36:X36),0) -> 36097 | J36: =36097285.7/1000 -> 36097.286 | L36: 0 | N36: 0 | P36: 0 | Q36: 0 | R36: 0 | S36: 0 | T36: 0 | U36: 0 | V36: 0 | W36: 0 | X36: 0
D37: b. | E37: Tabungan | H37: 20120 | I37: =ROUND(SUM(J37:X37),0) -> 0 | K37: 0 | L37: 0 | M37: 0 | N37: 0 | P37: 0 | Q37: 0 | R37: 0 | S37: 0 | T37: 0 | U37: 0 | V37: 0 | W37: 0 | X37: 0
D38: c. | E38: Simpanan Berjangka | H38: 20130 | I38: =ROUND(SUM(J38:X38),0) -> 157704 | J38: =+SUM(J39:J41) -> 0 | K38: =+SUM(K39:K41) -> 0 | L38: =+SUM(L39:L41) -> 0 | M38: =+SUM(M39:M41) -> 742.31957 | N38: =+SUM(N39:N41) -> 52592.767 | O38: =+SUM(O39:O41) -> 0 | P38: =+SUM(P39:P41) -> 104368.45 | Q38: =+SUM(Q39:Q41) -> 0 | ... X38: =+SUM(X39:X41) -> 0
E39: 1) | F39: Deposit on call | H39: 20131 | I39: =ROUND(SUM(J39:X39),0) -> 0 | J39: 0 | K39: 0 | L39: 0 | M39: 0 | N39: 0 | O39: 0 | P39: 0 | Q39: 0 | R39: 0 | S39: 0 | T39: 0 | U39: 0 | V39: 0 | W39: 0 | X39: 0
E40: 2) | F40: Deposito berjangka | H40: 20132 | I40: =ROUND(SUM(J40:X40),0) -> 157704 | M40: 742.31957 | N40: 52592.767 | O40: 0 | P40: 104368.45 | Q40: 0 | R40: 0 | S40: 0 | T40: 0 | U40: 0 | V40: 0 | W40: 0 | X40: 0
E41: 3) | F41: Lainnya | H41: 20139 | I41: =ROUND(SUM(J41:X41),0) -> 0
C42: 2. | D42: Kewajiban kepada Bank Indonesia | H42: 20200 | I42: =ROUND(SUM(J42:X42),0) -> 0
C43: 3. | D43: Kewajiban kepada bank lain | H43: 20300 | I43: =ROUND(SUM(J43:X43),0) -> 991773 | J43: 0 | K43: 0 | L43: =48670.6316735322-20000 -> 28670.632 | M43: 192654.58 | N43: =283912.018095605+20000 -> 303912.02 | O43: 27738.612 | P43: 63627.9 | Q43: 0 | R43: 0 | S43: =344750.30768752+419.14 -> 345169.45 | T43: 0 | U43: 0 | V43: 0 | W43: 0 | X43: 30000
C44: 4. | D44: Surat Berharga yang Diterbitkan | H44: 20400 | I44: =ROUND(SUM(J44:X44),0) -> 0 | J44: =+SUM(J45:J47) -> 0 | K44: =+SUM(K45:K47) -> 0 | L44: =+SUM(L45:L47) -> 0 | M44: =+SUM(M45:M47) -> 0 | N44: =+SUM(N45:N47) -> 0 | O44: =+SUM(O45:O47) -> 0 | P44: =+SUM(P45:P47) -> 0 | Q44: =+SUM(Q45:Q47) -> 0 | ... X44: =+SUM(X45:X47) -> 0
...

Sheet NY
A2: A | B2: B | C2: C | D2: D | E2: E | F2: F | G2: G | I2: H | J2: I | K2: J | L2: K | M2: L | N2: M | O2: N
B3: Formulir 4.b.
B4: MATURITY PROFILE REPORT - BNI NEW YORK AGENCY
B5: CONTRACTUAL BASED
B6: 45777
B7: Valuta Asing
I8: LIABILITIES KUMULATIF S.D 1 BULAN | J8: =O9 -> 1318744.6 | M8: =SUM(J14:L14) -> 1406607 | N8: =SUM(J59:L59) -> 37990.588 | O8: =M8+N8 -> 1444597.6 | P8: aset | Q8: =O8/O9 -> 1.0954339
I9: ASSET KUMULATIF S.D 1 BULAN | J9: =O8 -> 1444597.6 | K9: =+J9-J8 -> 125853 | L9: =+J9/J8*10000% -> 109.54339 | M9: =SUM(J34:L34) -> 1280754 | N9: =SUM(J68:L68) -> 37990.588 | O9: =+M9+N9 -> 1318744.6 | P9: kewajiban | W9: in Thousand USD
B10: Pos-Pos | H10: Sandi | I10: Saldo | J10: Time to Maturity *)
J11: up to 1 week | K11: > 1 week to 2 weeks | L11: > 2 weeks to 1 month | M11: > 1 month to 3 months | N11: > 3 months to 6 months | O11: > 6 months to 1 year | P11: > 1 y to 2 y | Q11: > 2 y to 3 y | R11: > 3 y to 4 y | S11: > 4 y to 5 y | T11: > 5 y to 7 y | U11: > 7 y to 10 y | V11: > 10 y to 15 y | W11: > 15 y to 20 y | X11: > 20 y
B13: I. | C13: NERACA
B14: A. | C14: Aset | H14: 10000 | I14: =ROUND(SUM(J14:X14),0) -> 2287215 | J14: =ROUND(+J15+J16+J17+J18+J25+J28+J31,0) -> 1360572 | K14: =ROUND(+K15+K16+K17+K18+K25+K28+K31,0) -> 42218 | L14: =ROUND(+L15+L16+L17+L18+L25+L28+L31,0) -> 3817 | M14: =ROUND(+M15+M16+M17+M18+M25+M28+M31,0) -> 45651 | N14: =ROUND(+N15+N16+N17+N18+N25+N28+N31,0) -> 30627 | O14: =ROUND(+O15+O16+O17+O18+O25+O28+O31,0) -> 56775 | P14: =ROUND(+P15+P16+P17+P18+P25+P28+P31,0) -> 122252 | Q14: =ROUND(+Q15+Q16+Q17+Q18+Q25+Q28+Q31,0) -> 262744 | ... X14: =ROUND(+X15+X16+X17+X18+X25+X28+X31,0) -> 3210
C15: 1. | D15: Kas | H15: 10100 | I15: =ROUND(SUM(J15:X15),0) -> 1 | J15: =+'[2]Maturity Profile (Eng)'!J15 -> 0.5401 | K15: =+'[2]Maturity Profile (Eng)'!K15 -> 0 | L15: =+'[2]Maturity Profile (Eng)'!L15 -> 0 | M15: =+'[2]Maturity Profile (Eng)'!M15 -> 0 | N15: =+'[2]Maturity Profile (Eng)'!N15 -> 0 | O15: =+'[2]Maturity Profile (Eng)'!O15 -> 0 | P15: =+'[2]Maturity Profile (Eng)'!P15 -> 0 | Q15: =+'[2]Maturity Profile (Eng)'!Q15 -> 0 | ... X15: =+'[2]Maturity Profile (Eng)'!X15 -> 0 | Y15: x | Z15: PRT.GLAJ650.PER - 100001 NY
C16: 2. | D16: Penempatan pada Bank Indonesia | H16: 10200 | I16: =ROUND(SUM(J16:X16),0) -> 0 | J16: =+'[2]Maturity Profile (Eng)'!J16 -> 0 | K16: =+'[2]Maturity Profile (Eng)'!K16 -> 0 | L16: =+'[2]Maturity Profile (Eng)'!L16 -> 0 | M16: =+'[2]Maturity Profile (Eng)'!M16 -> 0 | N16: =+'[2]Maturity Profile (Eng)'!N16 -> 0 | O16: =+'[2]Maturity Profile (Eng)'!O16 -> 0 | P16: =+'[2]Maturity Profile (Eng)'!P16 -> 0 | Q16: =+'[2]Maturity Profile (Eng)'!Q16 -> 0 | ... X16: =+'[2]Maturity Profile (Eng)'!X16 -> 0 | Z16: NOT AVAILABLE
C17: 3. | D17: Penempatan pada bank lain | H17: 10300 | I17: =ROUND(SUM(J17:X17),0) -> 1422989 | J17: =+'[2]Maturity Profile (Eng)'!J17 -> 1358988.6 | K17: =+'[2]Maturity Profile (Eng)'!K17 -> 40000 | L17: =+'[2]Maturity Profile (Eng)'!L17 -> 0 | M17: =+'[2]Maturity Profile (Eng)'!M17 -> 24000 | N17: =+'[2]Maturity Profile (Eng)'!N17 -> 0 | O17: =+'[2]Maturity Profile (Eng)'!O17 -> 0 | P17: =+'[2]Maturity Profile (Eng)'!P17 -> 0 | Q17: =+'[2]Maturity Profile (Eng)'!Q17 -> 0 | ... X17: =+'[2]Maturity Profile (Eng)'!X17 -> 0 | Y17: x | Z17: PRT.GLAJ650.PER - (NY) 102001+(NY) 102002+(IBF)110103 | AF17: =(243578452.62+130258.76+140000000)/1000 -> 383708.71
C18: 4. | D18: Surat Berharga **) | H18: 10400 | I18: =ROUND(SUM(J18:X18),0) -> 142900 | J18: =+J19+J24 -> 0 | K18: =+K19+K24 -> 0 | L18: =+L19+L24 -> 0 | M18: =+M19+M24 -> 5005.35 | N18: =+N19+N24 -> 0 | O18: =+O19+O24 -> 7482.2732 | P18: =+P19+P24 -> 13396.151 | Q18: =+Q19+Q24 -> 0 | ... X18: =+X19+X24 -> 3209.9
D19: a. | E19: Surat berharga korporasi | H19: 10420 | I19: =ROUND(SUM(J19:X19),0) -> 142900 | J19: =+SUM(J20:J23) -> 0 | K19: =+SUM(K20:K23) -> 0 | L19: =+SUM(L20:L23) -> 0 | M19: =+SUM(M20:M23) -> 5005.35 | N19: =+SUM(N20:N23) -> 0 | O19: =+SUM(O20:O23) -> 7482.2732 | P19: =+SUM(P20:P23) -> 13396.151 | Q19: =+SUM(Q20:Q23) -> 0 | ... X19: =+SUM(X20:X23) -> 3209.9
E20: 1) | F20: diperdagangkan | H20: 10421 | I20: =ROUND(SUM(J20:X20),0) -> 0 | J20: =+'[2]Maturity Profile (Eng)'!J20 -> 0 | K20: =+'[2]Maturity Profile (Eng)'!K20 -> 0 | L20: =+'[2]Maturity Profile (Eng)'!L20 -> 0 | M20: =+'[2]Maturity Profile (Eng)'!M20 -> 0 | N20: =+'[2]Maturity Profile (Eng)'!N20 -> 0 | O20: =+'[2]Maturity Profile (Eng)'!O20 -> 0 | P20: =+'[2]Maturity Profile (Eng)'!P20 -> 0 | Q20: =+'[2]Maturity Profile (Eng)'!Q20 -> 0 | ... X20: =+'[2]Maturity Profile (Eng)'!X20 -> 0
E21: 2) | F21: tersedia untuk dijual | H21: 10422 | I21: =ROUND(SUM(J21:X21),0) -> 74837 | J21: =+'[2]Maturity Profile (Eng)'!J21 -> 0 | K21: =+'[2]Maturity Profile (Eng)'!K21 -> 0 | L21: =+'[2]Maturity Profile (Eng)'!L21 -> 0 | M21: =+'[2]Maturity Profile (Eng)'!M21 -> 5005.35 | N21: =+'[2]Maturity Profile (Eng)'!N21 -> 0 | O21: =+'[2]Maturity Profile (Eng)'!O21 -> 4980.75 | P21: =+'[2]Maturity Profile (Eng)'!P21 -> 7390.6633 | Q21: =+'[2]Maturity Profile (Eng)'!Q21 -> 0 | ... X21: =+'[2]Maturity Profile (Eng)'!X21 -> 3209.9 | Y21: x | Z21: PRT.GLAJ650.PER - 115127+115130+115132+115135+115136+115182+115183 | AH21: =(60500000+12978.45+30000000+7500000+3633905.36+513059.34)/1000 -> 102159.94 | AI21: =I21 -> 74837 | AJ21: =AH21-AI21 -> 27322.943 | AK21: *difference due to accounting
E22: 3) | F22: dimiliki hingga jatuh tempo | H22: 10423 | I22: =ROUND(SUM(J22:X22),0) -> 68063 | J22: =+'[2]Maturity Profile (Eng)'!J22 -> 0 | K22: =+'[2]Maturity Profile (Eng)'!K22 -> 0 | L22: =+'[2]Maturity Profile (Eng)'!L22 -> 0 | M22: =+'[2]Maturity Profile (Eng)'!M22 -> 0 | N22: =+'[2]Maturity Profile (Eng)'!N22 -> 0 | O22: =+'[2]Maturity Profile (Eng)'!O22 -> 2501.5232 | P22: =+'[2]Maturity Profile (Eng)'!P22 -> 6005.4873 | Q22: =+'[2]Maturity Profile (Eng)'!Q22 -> 0 | ... X22: =+'[2]Maturity Profile (Eng)'!X22 -> 0 | Y22: x | Z22: PRT.GLAJ650.PER - 115147+115155+115156+115181 | AE22: =(70500000-418782.02)/1000 -> 70081.218 | AF22: =I22 -> 68063 | AG22: =AF22-AE22 -> -2018.218
E23: 4) | F23: pinjaman yang diberikan dan piutang | H23: 10424 | I23: =ROUND(SUM(J23:X23),0) -> 0 | J23: =+'[2]Maturity Profile (Eng)'!J23 -> 0 | K23: =+'[2]Maturity Profile (Eng)'!K23 -> 0 | L23: =+'[2]Maturity Profile (Eng)'!L23 -> 0 | M23: =+'[2]Maturity Profile (Eng)'!M23 -> 0 | N23: =+'[2]Maturity Profile (Eng)'!N23 -> 0 | O23: =+'[2]Maturity Profile (Eng)'!O23 -> 0 | P23: =+'[2]Maturity Profile (Eng)'!P23 -> 0 | Q23: =+'[2]Maturity Profile (Eng)'!Q23 -> 0 | ... X23: =+'[2]Maturity Profile (Eng)'!X23 -> 0 | AA23: repo= 115144-115181 | AE23: 0
D24: b. | E24: Lainnya | H24: 10490 | I24: =ROUND(SUM(J24:X24),0) -> 0 | J24: =+'[2]Maturity Profile (Eng)'!J24 -> 0 | K24: =+'[2]Maturity Profile (Eng)'!K24 -> 0 | L24: =+'[2]Maturity Profile (Eng)'!L24 -> 0 | M24: =+'[2]Maturity Profile (Eng)'!M24 -> 0 | N24: =+'[2]Maturity Profile (Eng)'!N24 -> 0 | O24: =+'[2]Maturity Profile (Eng)'!O24 -> 0 | P24: =+'[2]Maturity Profile (Eng)'!P24 -> 0 | Q24: =+'[2]Maturity Profile (Eng)'!Q24 -> 0 | ... X24: =+'[2]Maturity Profile (Eng)'!X24 -> 0
C25: 5. | D25: Kredit Yang Diberikan | H25: 10500 | I25: =ROUND(SUM(J25:X25),0) -> 721326 | J25: =+SUM(J26:J27) -> 1583.2945 | K25: =+SUM(K26:K27) -> 2218.35 | L25: =+SUM(L26:L27) -> 3816.9479 | M25: =+SUM(M26:M27) -> 16646.088 | N25: =+SUM(N26:N27) -> 30627.221 | O25: =+SUM(O26:O27) -> 49292.513 | P25: =+SUM(P26:P27) -> 108855.87 | Q25: =+SUM(Q26:Q27) -> 262743.62 | ... X25: =+SUM(X26:X27) -> 0
D26: a. | E26: belum jatuh tempo | H26: 10510 | I26: =ROUND(SUM(J26:X26),0) -> 721326 | J26: =+'[2]Maturity Profile (Eng)'!J26 -> 1583.2945 | K26: =+'[2]Maturity Profile (Eng)'!K26 -> 2218.35 | L26: =+'[2]Maturity Profile (Eng)'!L26 -> 3816.9479 | M26: =+'[2]Maturity Profile (Eng)'!M26 -> 16646.088 | N26: =+'[2]Maturity Profile (Eng)'!N26 -> 30627.221 | O26: =+'[2]Maturity Profile (Eng)'!O26 -> 49292.513 | P26: =+'[2]Maturity Profile (Eng)'!P26 -> 108855.87 | Q26: =+'[2]Maturity Profile (Eng)'!Q26 -> 262743.62 | ... X26: =+'[2]Maturity Profile (Eng)'!X26 -> 0 | Z26: FROM loan sheet
D27: b. | E27: sudah jatuh tempo ***) | H27: 10520 | I27: =ROUND(SUM(J27:X27),0) -> 0 | J27: =+'[2]Maturity Profile (Eng)'!J27 -> 0 | K27: =+'[2]Maturity Profile (Eng)'!K27 -> 0 | L27: =+'[2]Maturity Profile (Eng)'!L27 -> 0 | M27: =+'[2]Maturity Profile (Eng)'!M27 -> 0 | N27: =+'[2]Maturity Profile (Eng)'!N27 -> 0 | O27: =+'[2]Maturity Profile (Eng)'!O27 -> 0 | P27: =+'[2]Maturity Profile (Eng)'!P27 -> 0 | Q27: =+'[2]Maturity Profile (Eng)'!Q27 -> 0 | ... X27: =+'[2]Maturity Profile (Eng)'!X27 -> 0 | Z27: FROM loan sheet
C28: 6. | D28: Tagihan lainnya | H28: 10700 | I28: =ROUND(SUM(J28:X28),0) -> 0 | J28: =+SUM(J29:J30) -> 0 | K28: =+SUM(K29:K30) -> 0 | L28: =+SUM(L29:L30) -> 0 | M28: =+SUM(M29:M30) -> 0 | N28: =+SUM(N29:N30) -> 0 | O28: =+SUM(O29:O30) -> 0 | P28: =+SUM(P29:P30) -> 0 | Q28: =+SUM(Q29:Q30) -> 0 | ... X28: =+SUM(X29:X30) -> 0
D29: a. | E29: Tagihan atas Surat Berharga yang dibeli dengan janji dijual kembali (Reverse Repo) | H29: 10710 | I29: =ROUND(SUM(J29:X29),0) -> 0 | J29: =+'[2]Maturity Profile (Eng)'!J29 -> 0 | K29: =+'[2]Maturity Profile (Eng)'!K29 -> 0 | L29: =+'[2]Maturity Profile (Eng)'!L29 -> 0 | M29: =+'[2]Maturity Profile (Eng)'!M29 -> 0 | N29: =+'[2]Maturity Profile (Eng)'!N29 -> 0 | O29: =+'[2]Maturity Profile (Eng)'!O29 -> 0 | P29: =+'[2]Maturity Profile (Eng)'!P29 -> 0 | Q29: =+'[2]Maturity Profile (Eng)'!Q29 -> 0 | ... X29: =+'[2]Maturity Profile (Eng)'!X29 -> 0
D30: b. | E30: Lainnya | H30: 10790 | I30: =ROUND(SUM(J30:X30),0) -> 0 | J30: =+'[2]Maturity Profile (Eng)'!J30 -> 0 | K30: =+'[2]Maturity Profile (Eng)'!K30 -> 0 | L30: =+'[2]Maturity Profile (Eng)'!L30 -> 0 | M30: =+'[2]Maturity Profile (Eng)'!M30 -> 0 | N30: =+'[2]Maturity Profile (Eng)'!N30 -> 0 | O30: =+'[2]Maturity Profile (Eng)'!O30 -> 0 | P30: =+'[2]Maturity Profile (Eng)'!P30 -> 0 | Q30: =+'[2]Maturity Profile (Eng)'!Q30 -> 0 | ... X30: =+'[2]Maturity Profile (Eng)'!X30 -> 0 | Y30: x | Z30: PRT.GLAJ650.PER - (NY) 150004 | AD30: ='[3]Export Bills Discounted'!#REF!/1000 -> #REF! | AE30: =I30 -> 0 | AF30: =AD30-AE30 -> #REF!
C31: 7. | D31: Lain-lain | H31: 10600 | I31: =ROUND(SUM(J31:X31),0) -> 0 | J31: =+'[2]Maturity Profile (Eng)'!I31 -> 0 | K31: =+'[2]Maturity Profile (Eng)'!J31 -> 0 | L31: =+'[2]Maturity Profile (Eng)'!K31 -> 0 | M31: =+'[2]Maturity Profile (Eng)'!L31 -> 0 | N31: =+'[2]Maturity Profile (Eng)'!M31 -> 0 | O31: =+'[2]Maturity Profile (Eng)'!N31 -> 0 | P31: =+'[2]Maturity Profile (Eng)'!O31 -> 0 | Q31: =+'[2]Maturity Profile (Eng)'!P31 -> 0 | ... X31: =+'[2]Maturity Profile (Eng)'!W31 -> 0 | Y31: x | Z31: PRT.GLAJ650.PER - (NY) 150001 | AD31: ='[3]TRADE ADVANCE'!D8/1000 -> 0 | AE31: =I31 -> 0 | AF31: =AD31-AE31 -> 0
AF32: .
B34: B. | C34: Kewajiban | H34: 20000 | I34: =ROUND(SUM(J34:X34),0) -> 1448139 | J34: =ROUND(+J35+J42+J43+J44+J48+J51+J54,0) -> 1230854 | K34: =ROUND(+K35+K42+K43+K44+K48+K51+K54,0) -> 2900 | L34: =ROUND(+L35+L42+L43+L44+L48+L51+L54,0) -> 47000 | M34: =ROUND(+M35+M42+M43+M44+M48+M51+M54,0) -> 43585 | N34: =ROUND(+N35+N42+N43+N44+N48+N51+N54,0) -> 0 | O34: =ROUND(+O35+O42+O43+O44+O48+O51+O54,0) -> 8800 | P34: =ROUND(+P35+P42+P43+P44+P48+P51+P54,0) -> 0 | Q34: =ROUND(+Q35+Q42+Q43+Q44+Q48+Q51+Q54,0) -> 0 | ... X34: =ROUND(+X35+X42+X43+X44+X48+X51+X54,0) -> 0
C35: 1. | D35: Dana Pihak Ketiga | H35: 20100 | I35: =ROUND(SUM(J35:X35),0) -> 93239 | J35: =+J36+J37+J38 -> 92853.899 | K35: =+K36+K37+K38 -> 0 | L35: =+L36+L37+L38 -> 0 | M35: =+M36+M37+M38 -> 385 | N35: =+N36+N37+N38 -> 0 | O35: =+O36+O37+O38 -> 0 | P35: =+P36+P37+P38 -> 0 | Q35: =+Q36+Q37+Q38 -> 0 | ... X35: =+X36+X37+X38 -> 0
D36: a. | E36: Giro | H36: 20110 | I36: =ROUND(SUM(J36:X36),0) -> 92854 | J36: =+'[2]Maturity Profile (Eng)'!J36 -> 92853.899 | K36: =+'[2]Maturity Profile (Eng)'!K36 -> 0 | L36: =+'[2]Maturity Profile (Eng)'!L36 -> 0 | M36: =+'[2]Maturity Profile (Eng)'!M36 -> 0 | N36: =+'[2]Maturity Profile (Eng)'!N36 -> 0 | O36: =+'[2]Maturity Profile (Eng)'!O36 -> 0 | P36: =+'[2]Maturity Profile (Eng)'!P36 -> 0 | Q36: =+'[2]Maturity Profile (Eng)'!Q36 -> 0 | ... X36: =+'[2]Maturity Profile (Eng)'!X36 -> 0 | Y36: x | Z36: PRT.GLAJ650.PER - (NY) 210001+210002+210006+251003 | AG36: =+(70600321.76+87577.38+12766595.2+201497.59)/1000 -> 83655.992
D37: b. | E37: Tabungan | H37: 20120 | I37: =ROUND(SUM(J37:X37),0) -> 0 | J37: =+'[2]Maturity Profile (Eng)'!J37 -> 0 | K37: =+'[2]Maturity Profile (Eng)'!K37 -> 0 | L37: =+'[2]Maturity Profile (Eng)'!L37 -> 0 | M37: =+'[2]Maturity Profile (Eng)'!M37 -> 0 | N37: =+'[2]Maturity Profile (Eng)'!N37 -> 0 | O37: =+'[2]Maturity Profile (Eng)'!O37 -> 0 | P37: =+'[2]Maturity Profile (Eng)'!P37 -> 0 | Q37: =+'[2]Maturity Profile (Eng)'!Q37 -> 0 | ... X37: =+'[2]Maturity Profile (Eng)'!X37 -> 0
D38: c. | E38: Simpanan Berjangka | H38: 20130 | I38: =ROUND(SUM(J38:X38),0) -> 385 | J38: =+SUM(J39:J41) -> 0 | K38: =+SUM(K39:K41) -> 0 | L38: =+SUM(L39:L41) -> 0 | M38: =+SUM(M39:M41) -> 385 | N38: =+SUM(N39:N41) -> 0 | O38: =+SUM(O39:O41) -> 0 | P38: =+SUM(P39:P41) -> 0 | Q38: =+SUM(Q39:Q41) -> 0 | ... X38: =+SUM(X39:X41) -> 0
E39: 1) | F39: Deposit on call | H39: 20131 | I39: =ROUND(SUM(J39:X39),0) -> 0 | J39: =+'[2]Maturity Profile (Eng)'!J39 -> 0 | K39: =+'[2]Maturity Profile (Eng)'!K39 -> 0 | L39: =+'[2]Maturity Profile (Eng)'!L39 -> 0 | M39: =+'[2]Maturity Profile (Eng)'!M39 -> 0 | N39: =+'[2]Maturity Profile (Eng)'!N39 -> 0 | O39: =+'[2]Maturity Profile (Eng)'!O39 -> 0 | P39: =+'[2]Maturity Profile (Eng)'!P39 -> 0 | Q39: =+'[2]Maturity Profile (Eng)'!Q39 -> 0 | ... X39: =+'[2]Maturity Profile (Eng)'!X39 -> 0
E40: 2) | F40: Deposito berjangka | H40: 20132 | I40: =ROUND(SUM(J40:X40),0) -> 385 | J40: =+'[2]Maturity Profile (Eng)'!J40 -> 0 | K40: =+'[2]Maturity Profile (Eng)'!K40 -> 0 | L40: =+'[2]Maturity Profile (Eng)'!L40 -> 0 | M40: =+'[2]Maturity Profile (Eng)'!M40 -> 385 | N40: =+'[2]Maturity Profile (Eng)'!N40 -> 0 | O40: =+'[2]Maturity Profile (Eng)'!O40 -> 0 | P40: =+'[2]Maturity Profile (Eng)'!P40 -> 0 | Q40: =+'[2]Maturity Profile (Eng)'!Q40 -> 0 | ... X40: =+'[2]Maturity Profile (Eng)'!X40 -> 0 | Y40: x | Z40: PRT.GLAJ650.PER - 210031 (IBF + NYA) | AD40: ='[3]Maturity Profile (Eng)'!AD40 -> 75485 | AE40: =I40 -> 385 | AF40: =AD40-AE40 -> 75100
E41: 3) | F41: Lainnya | H41: 20139 | I41: =ROUND(SUM(J41:X41),0) -> 0 | J41: =+'[2]Maturity Profile (Eng)'!J41 -> 0 | K41: =+'[2]Maturity Profile (Eng)'!K41 -> 0 | L41: =+'[2]Maturity Profile (Eng)'!L41 -> 0 | M41: =+'[2]Maturity Profile (Eng)'!M41 -> 0 | N41: =+'[2]Maturity Profile (Eng)'!N41 -> 0 | O41: =+'[2]Maturity Profile (Eng)'!O41 -> 0 | P41: =+'[2]Maturity Profile (Eng)'!P41 -> 0 | Q41: =+'[2]Maturity Profile (Eng)'!Q41 -> 0 | ... X41: =+'[2]Maturity Profile (Eng)'!X41 -> 0
C42: 2. | D42: Kewajiban kepada Bank Indonesia | H42: 20200 | I42: =ROUND(SUM(J42:X42),0) -> 0 | J42: =+'[2]Maturity Profile (Eng)'!J42 -> 0 | K42: =+'[2]Maturity Profile (Eng)'!K42 -> 0 | L42: =+'[2]Maturity Profile (Eng)'!L42 -> 0 | M42: =+'[2]Maturity Profile (Eng)'!M42 -> 0 | N42: =+'[2]Maturity Profile (Eng)'!N42 -> 0 | O42: =+'[2]Maturity Profile (Eng)'!O42 -> 0 | P42: =+'[2]Maturity Profile (Eng)'!P42 -> 0 | Q42: =+'[2]Maturity Profile (Eng)'!Q42 -> 0 | ... X42: =+'[2]Maturity Profile (Eng)'!X42 -> 0
C43: 3. | D43: Kewajiban kepada bank lain | H43: 20300 | I43: =ROUND(SUM(J43:X43),0) -> 1354900 | J43: =+'[2]Maturity Profile (Eng)'!J43 -> 1138000 | K43: =+'[2]Maturity Profile (Eng)'!K43 -> 2900 | L43: =+'[2]Maturity Profile (Eng)'!L43 -> 47000 | M43: =+'[2]Maturity Profile (Eng)'!M43 -> 43200 | N43: =+'[2]Maturity Profile (Eng)'!N43 -> 0 | O43: =+'[2]Maturity Profile (Eng)'!O43 -> 8800 | P43: =+'[2]Maturity Profile (Eng)'!P43 -> 0 | Q43: =+'[2]Maturity Profile (Eng)'!Q43 -> 0 | ... X43: =+'[2]Maturity Profile (Eng)'!X43 -> 0 | Y43: z | Z43: PRT.GLAJ650.PER - (IBF)252001+ (IBF)253001+(IBF)220001 | AE43: ='[3]Maturity Profile (Eng)'!AE43 -> 181000 | AF43: =I43 -> 1354900 | AG43: =AE43-AF43 -> -1173900
...

Sheet SEO
A2: A | B2: B | C2: C | D2: D | E2: E | F2: F | G2: G | I2: H | J2: I | K2: J | L2: K | M2: L | N2: M | O2: N
B3: Formulir 4.b.
B4: MATURITY PROFILE REPORT - BNI SEOUL Branch
B5: CONTRACTUAL BASED
B6: 46203
B7: Valuta Asing
I8: 1541.5 | J8: USD/KRW | K8: =SUM(J14:L14)+SUM(J59:L59) -> 37739 | L8: =K8-K9 -> 35212
K9: =SUM(J34:L34)+SUM(J68:L68) -> 2527 | W9: in Thousand USD
B10: Pos-Pos | H10: Sandi | I10: Saldo | J10: Time to Maturity *)
J11: up to 1 week | K11: > 1 week to 2 weeks | L11: > 2 weeks to 1 month | M11: > 1 month to 3 months | N11: > 3 months to 6 months | O11: > 6 months to 1 year | P11: > 1 y to 2 y | Q11: > 2 y to 3 y | R11: > 3 y to 4 y | S11: > 4 y to 5 y | T11: > 5 y to 7 y | U11: > 7 y to 10 y | V11: > 10 y to 15 y | W11: > 15 y to 20 y | X11: > 20 y
B13: I. | C13: NERACA
B14: A. | C14: Aset | H14: 10000 | I14: =ROUND(SUM(J14:X14),0) -> 445137 | J14: =ROUND(+J15+J16+J17+J18+J25+J28+J31,0) -> 37739 | K14: =ROUND(+K15+K16+K17+K18+K25+K28+K31,0) -> 0 | L14: =ROUND(+L15+L16+L17+L18+L25+L28+L31,0) -> 0 | M14: =ROUND(+M15+M16+M17+M18+M25+M28+M31,0) -> 35867 | N14: =ROUND(+N15+N16+N17+N18+N25+N28+N31,0) -> 29850 | O14: =ROUND(+O15+O16+O17+O18+O25+O28+O31,0) -> 32060 | P14: =ROUND(+P15+P16+P17+P18+P25+P28+P31,0) -> 40368 | Q14: =ROUND(+Q15+Q16+Q17+Q18+Q25+Q28+Q31,0) -> 74553 | ... X14: =ROUND(+X15+X16+X17+X18+X25+X28+X31,0) -> 0
C15: 1. | D15: Kas | H15: 10100 | I15: =ROUND(SUM(J15:X15),0) -> 264 | J15: =((406390234.5/$I$8)/1000) -> 263.63298
C16: 2. | D16: Penempatan pada Bank Indonesia | H16: 10200 | I16: =ROUND(SUM(J16:X16),0) -> 0
C17: 3. | D17: Penempatan pada bank lain | H17: 10300 | I17: =ROUND(SUM(J17:X17),0) -> 37605 | J17: =26475000/1000+11000000/1000 -> 37475 | K17: =0/$I$8/1000 -> 0 | L17: =0/$I$8/1000 -> 0 | M17: =+(200000000/I8/1000) -> 129.74376
C18: 4. | D18: Surat Berharga **) | H18: 10400 | I18: =ROUND(SUM(J18:X18),0) -> 169701 | J18: =+J19+J24 -> 0 | K18: =+K19+K24 -> 0 | L18: =+L19+L24 -> 0 | M18: =+M19+M24 -> 0 | N18: =+N19+N24 -> 11115 | O18: =+O19+O24 -> 13120 | P18: =+P19+P24 -> 25368 | Q18: =+Q19+Q24 -> 36650 | ... X18: =+X19+X24 -> 0
D19: a. | E19: Surat berharga korporasi | H19: 10420 | I19: =ROUND(SUM(J19:X19),0) -> 2000 | J19: =+SUM(J20:J23) -> 0 | K19: =+SUM(K20:K23) -> 0 | L19: =+SUM(L20:L23) -> 0 | M19: =+SUM(M20:M23) -> 0 | N19: =+SUM(N20:N23) -> 0 | O19: =+SUM(O20:O23) -> 0 | P19: =+SUM(P20:P23) -> 0 | Q19: =+SUM(Q20:Q23) -> 0 | ... X19: =+SUM(X20:X23) -> 0
E20: 1) | F20: diperdagangkan | H20: 10421 | I20: =ROUND(SUM(J20:X20),0) -> 0
E21: 2) | F21: tersedia untuk dijual | H21: 10422 | I21: =ROUND(SUM(J21:X21),0) -> 0
E22: 3) | F22: dimiliki hingga jatuh tempo | H22: 10423 | I22: =ROUND(SUM(J22:X22),0) -> 2000 | J22: 0 | S22: 2000
E23: 4) | F23: pinjaman yang diberikan dan piutang | H23: 10424 | I23: =ROUND(SUM(J23:X23),0) -> 0
D24: b. | E24: Lainnya | H24: 10490 | I24: =ROUND(SUM(J24:X24),0) -> 167701 | J24: 0 | K24: 0 | L24: 0 | M24: 0 | N24: 11115 | O24: 13120 | P24: 25368 | Q24: 36650 | R24: 31022 | S24: 34608 | T24: 15818 | U24: 0
C25: 5. | D25: Kredit Yang Diberikan | H25: 10500 | I25: =ROUND(SUM(J25:X25),0) -> 237567 | J25: =+SUM(J26:J27) -> 0 | K25: =+SUM(K26:K27) -> 0 | L25: =+SUM(L26:L27) -> 0 | M25: =+SUM(M26:M27) -> 35736.968 | N25: =+SUM(N26:N27) -> 18735.02 | O25: =+SUM(O26:O27) -> 18940 | P25: =+SUM(P26:P27) -> 15000 | Q25: =+SUM(Q26:Q27) -> 37903.317 | ... X25: =+SUM(X26:X27) -> 0
D26: a. | E26: belum jatuh tempo | H26: 10510 | I26: =ROUND(SUM(J26:X26),0) -> 237567 | J26: 0 | K26: 0 | L26: 0 | M26: 35736.968 | N26: 18735.02 | O26: 18940 | P26: 15000 | Q26: 37903.317 | R26: 51267.07 | S26: 15000 | T26: 1850 | U26: 43135.09
D27: b. | E27: sudah jatuh tempo ***) | H27: 10520 | I27: =ROUND(SUM(J27:X27),0) -> 0
C28: 6. | D28: Tagihan lainnya | H28: 10700 | I28: =ROUND(SUM(J28:X28),0) -> 0 | J28: =+SUM(J29:J30) -> 0 | K28: =+SUM(K29:K30) -> 0 | L28: =+SUM(L29:L30) -> 0 | M28: =+SUM(M29:M30) -> 0 | N28: =+SUM(N29:N30) -> 0 | O28: =+SUM(O29:O30) -> 0 | P28: =+SUM(P29:P30) -> 0 | Q28: =+SUM(Q29:Q30) -> 0 | ... X28: =+SUM(X29:X30) -> 0
D29: a. | E29: Tagihan atas Surat Berharga yang dibeli dengan janji dijual kembali (Reverse Repo) | H29: 10710 | I29: =ROUND(SUM(J29:X29),0) -> 0
D30: b. | E30: Lainnya | H30: 10790 | I30: =ROUND(SUM(J30:X30),0) -> 0
C31: 7. | D31: Lain-lain | H31: 10600 | I31: =ROUND(SUM(J31:X31),0) -> 0 | J31: 0 | K31: 0 | L31: 0 | M31: 0 | N31: 0 | O31: 0 | P31: 0 | Q31: 0 | R31: 0 | S31: 0 | T31: 0 | U31: 0
J32: =J17-[4]SEO!$J$17 -> 14225
B34: B. | C34: Kewajiban | H34: 20000 | I34: =ROUND(SUM(J34:X34),0) -> 2716 | J34: =ROUND(+J35+J42+J43+J44+J48+J51+J54,0) -> 2442 | K34: =ROUND(+K35+K42+K43+K44+K48+K51+K54,0) -> 0 | L34: =ROUND(+L35+L42+L43+L44+L48+L51+L54,0) -> 85 | M34: =ROUND(+M35+M42+M43+M44+M48+M51+M54,0) -> 189 | N34: =ROUND(+N35+N42+N43+N44+N48+N51+N54,0) -> 0 | O34: =ROUND(+O35+O42+O43+O44+O48+O51+O54,0) -> 0 | P34: =ROUND(+P35+P42+P43+P44+P48+P51+P54,0) -> 0 | Q34: =ROUND(+Q35+Q42+Q43+Q44+Q48+Q51+Q54,0) -> 0 | ... X34: =ROUND(+X35+X42+X43+X44+X48+X51+X54,0) -> 0
C35: 1. | D35: Dana Pihak Ketiga | H35: 20100 | I35: =ROUND(SUM(J35:X35),0) -> 2716 | J35: =+J36+J37+J38 -> 2441.8188 | K35: =+K36+K37+K38 -> 0 | L35: =+L36+L37+L38 -> 85.32334 | M35: =+M36+M37+M38 -> 189.19936 | N35: =+N36+N37+N38 -> 0 | O35: =+O36+O37+O38 -> 0 | P35: =+P36+P37+P38 -> 0 | Q35: =+Q36+Q37+Q38 -> 0 | ... X35: =+X36+X37+X38 -> 0
D36: a. | E36: Giro | H36: 20110 | I36: =ROUND(SUM(J36:X36),0) -> 1274 | J36: =+(1963126628.82/I8/1000) -> 1273.5171
D37: b. | E37: Tabungan | H37: 20120 | I37: =ROUND(SUM(J37:X37),0) -> 1137 | J37: =+(1752307580.88/I8/1000) -> 1136.7548
D38: c. | E38: Simpanan Berjangka | H38: 20130 | I38: =ROUND(SUM(J38:X38),0) -> 306 | J38: =+SUM(J39:J41) -> 31.54688 | K38: =+SUM(K39:K41) -> 0 | L38: =+SUM(L39:L41) -> 85.32334 | M38: =+SUM(M39:M41) -> 189.19936 | N38: =+SUM(N39:N41) -> 0 | O38: =+SUM(O39:O41) -> 0 | P38: =+SUM(P39:P41) -> 0 | Q38: =+SUM(Q39:Q41) -> 0 | ... X38: =+SUM(X39:X41) -> 0
E39: 1) | F39: Deposit on call | H39: 20131 | I39: =ROUND(SUM(J39:X39),0) -> 0
E40: 2) | F40: Deposito berjangka | H40: 20132 | I40: =ROUND(SUM(J40:X40),0) -> 306 | J40: 31.54688 | K40: 0 | L40: 85.32334 | M40: 189.19936 | N40: 0 | O40: 0 | P40: 0 | Q40: 0 | R40: 0 | S40: 0 | T40: 0 | U40: 0 | V40: 0
E41: 3) | F41: Lainnya | H41: 20139 | I41: =ROUND(SUM(J41:X41),0) -> 0
C42: 2. | D42: Kewajiban kepada Bank Indonesia | H42: 20200 | I42: =ROUND(SUM(J42:X42),0) -> 0
C43: 3. | D43: Kewajiban kepada bank lain | H43: 20300 | I43: =ROUND(SUM(J43:X43),0) -> 0 | J43: 0 | K43: 0 | M43: 0 | Q43: 0 | R43: 0
...

Sheet SG
A3: A | B3: B | C3: C | D3: D | E3: E | F3: F | G3: G | I3: H | J3: I | K3: J | L3: K | M3: L | N3: M | O3: N
B4: Formulir 4.b.
B5: MATURITY PROFILE REPORT - BNI SINGAPORE BRANCH
B6: CONTRACTUAL BASED
B7: 46203
B8: Valuta Asing | M8: Aset | N8: =SUM(J16:L16)+SUM(J61:L61) -> 490287 | O8: =N8-N9 -> 58469
M9: Kewajiban | N9: =SUM(J36:L36)+SUM(J70:L70)-N10 -> 431818
M10: rollover borrow HO | N10: 118000 | W10: in Thousand USD
B11: Pos-Pos | H11: Sandi | I11: Saldo | J11: \
J12: up to 1 week | K12: > 1 week to 2 weeks | L12: > 2 weeks to 1 month | M12: > 1 month to 3 months | N12: > 3 months to 6 months | O12: > 6 months to 1 year | P12: > 1 y to 2 y | Q12: > 2 y to 3 y | R12: > 3 y to 4 y | S12: > 4 y to 5 y | T12: > 5 y to 7 y | U12: > 7 y to 10 y | V12: > 10 y to 15 y | W12: > 15 y to 20 y | X12: > 20 y
J14: =B7+7 -> 46210 | K14: =B7+14 -> 46217 | L14: 15 Jul - 31 Jul | M14: Aug - Sep 26 | N14: Oct - Dec 26 | O14: Jan 27 - Jun 27 | P14: Jul 27 - Jun 28 | Q14: Jul 28 - Jun 29 | R14: Jul 29 - Jun 30 | S14: Jul 30 - Jun 31 | T14: Jul 31 - Jun 33 | U14: Jul 33 - Jun 36 | V14: Jul 36 - Jun 41 | W14: Jul 41 - Jun 46 | X14: > Jun 46
B15: I. | C15: NERACA
B16: A. | C16: Aset | H16: 10000 | I16: =ROUND(SUM(J16:X16),0) -> 1900794 | J16: =ROUND(+J17+J18+J19+J20+J27+J30+J33,0) -> 318616 | K16: =ROUND(+K17+K18+K19+K20+K27+K30+K33,0) -> 34599 | L16: =ROUND(+L17+L18+L19+L20+L27+L30+L33,0) -> 17072 | M16: =ROUND(+M17+M18+M19+M26+M27+M30+M33,0) -> 110939 | N16: =ROUND(+N17+N18+N19+N26+N27+N30+N33,0) -> 107407 | O16: =ROUND(+O17+O18+O19+O26+O27+O30+O33,0) -> 92732 | P16: =ROUND(+P17+P18+P19+P26+P27+P30+P33,0) -> 427856 | Q16: =ROUND(+Q17+Q18+Q19+Q26+Q27+Q30+Q33,0) -> 211102 | R16: =ROUND(+R17+R18+R19+R26+R27+R30+R33,0) -> 282928 | S16: =ROUND(+S17+S18+S19+S26+S27+S30+S33,0) -> 169654 | T16: =ROUND(+T17+T18+T19+T26+T27+T30+T33,0) -> 127889 | ... X16: =ROUND(+X17+X18+X19+X26+X27+X30+X33,0) -> 0
C17: 1. | D17: Kas | H17: 10100 | I17: =ROUND(SUM(J17:X17),0) -> 192339 | J17: 192338.56 | K17: 0 | L17: 0 | M17: 0 | N17: 0 | O17: 0 | P17: 0 | Q17: 0 | R17: 0 | S17: 0 | T17: 0 | U17: 0 | V17: 0 | W17: 0 | X17: 0 | Y17: 1011+1012+1013
C18: 2. | D18: Penempatan pada Bank Indonesia | H18: 10200 | I18: =ROUND(SUM(J18:X18),0) -> 0 | K18: 0
C19: 3. | D19: Penempatan pada bank lain | H19: 10300 | I19: =ROUND(SUM(J19:X19),0) -> 250000 | J19: 100000 | S19: 150000
C20: 4. | D20: Surat Berharga **) | H20: 10400 | I20: =ROUND(SUM(J20:X20),0) -> 241831 | J20: =SUM(J21:J26) -> 0 | K20: =SUM(K21:K26) -> 0 | L20: =SUM(L21:L26) -> 0 | M20: =SUM(M21:M26) -> 0 | N20: =SUM(N21:N26) -> 9992 | O20: =SUM(O21:O26) -> 74160.9 | P20: =SUM(P21:P26) -> 54820.074 | Q20: =SUM(Q21:Q26) -> 32262.004 | ... X20: =SUM(X21:X26) -> 0
D21: a. | E21: Surat berharga korporasi | H21: 10420 | I21: =ROUND(SUM(J21:X21),0) -> 0 | J21: =J23 -> 0 | K21: =K23 -> 0 | L21: =L23 -> 0 | M21: =M23 -> 0 | N21: =N23 -> 0 | O21: =O23 -> 0 | P21: =P23 -> 0 | Q21: =Q23 -> 0 | ... X21: =X23 -> 0
E22: 1) | F22: diperdagangkan | H22: 10421 | I22: =ROUND(SUM(J22:X22),0) -> 0 | L22: 0 | M22: 0 | U22: 0
E23: 2) | F23: tersedia untuk dijual | H23: 10422 | I23: =ROUND(SUM(J23:X23),0) -> 0 | J23: 0 | K23: 0 | L23: 0 | M23: 0 | N23: 0 | O23: 0 | P23: 0 | Q23: 0 | R23: 0 | S23: 0 | T23: 0 | U23: 0 | V23: 0 | W23: 0 | X23: 0
E24: 3) | F24: dimiliki hingga jatuh tempo | H24: 10423 | I24: =ROUND(SUM(J24:X24),0) -> 0 | P24: 0 | T24: .
E25: 4) | F25: pinjaman yang diberikan dan piutang | H25: 10424 | I25: 0 | P25: 0 | Z25: 2195
D26: b. | E26: Lainnya | H26: 10490 | I26: =SUM(J26:X26) -> 241830.78 | N26: 9992 | O26: 74160.9 | P26: 54820.074 | Q26: 32262.004 | R26: 46177.678 | S26: 19654.45 | T26: 4763.67
C27: 5. | D27: Kredit Yang Diberikan | H27: 10500 | I27: =ROUND(SUM(J27:X27),0) -> 1201171 | J27: =+SUM(J28:J29) -> 10822.839 | K27: =K29+K28 -> 34599.409 | L27: =+SUM(L28:L29) -> 17071.839 | M27: =+SUM(M28:M29) -> 110938.54 | N27: =+SUM(N28:N29) -> 97415.245 | O27: =+SUM(O28:O29) -> 18571.424 | P27: =+SUM(P28:P29) -> 373035.95 | Q27: =+SUM(Q28:Q29) -> 178840.43 | R27: =+SUM(R28:R29) -> 236750.18 | S27: =+SUM(S28:S29) -> 0 | ... X27: =+SUM(X28:X29) -> 0
D28: a. | E28: belum jatuh tempo | H28: 10510 | I28: =ROUND(SUM(J28:X28),0) -> 1201171 | J28: 10822.839 | K28: 34599.409 | L28: 17071.839 | M28: 110938.54 | N28: 97415.245 | O28: 18571.424 | P28: 373035.95 | Q28: 178840.43 | R28: 236750.18 | S28: 0 | T28: 123125 | U28: 0 | V28: 0 | W28: 0 | X28: 0 | Y28: 0
D29: b. | E29: sudah jatuh tempo ***) | H29: 10520 | I29: =ROUND(SUM(J29:X29),0) -> 0 | U29: 0
C30: 6. | D30: Tagihan lainnya | H30: 10700 | I30: =ROUND(SUM(J30:X30),0) -> 0 | J30: =+SUM(J31:J32) -> 0 | K30: =+SUM(K31:K32) -> 0 | L30: =+L31+L32 -> 0 | M30: =+SUM(M31:M32) -> 0 | N30: =+SUM(N31:N32) -> 0 | O30: =+SUM(O31:O32) -> 0 | P30: =+SUM(P31:P32) -> 0 | Q30: =+SUM(Q31:Q32) -> 0 | R30: =+SUM(R31:R32) -> 0 | S30: =+SUM(S31:S32) -> 0 | T30: =+SUM(T31:T32) -> 0 | ... X30: =+SUM(X31:X32) -> 0
D31: a. | E31: Tagihan atas Surat Berharga yang dibeli dengan janji dijual kembali (Reverse Repo) | H31: 10710 | I31: =ROUND(SUM(J31:X31),0) -> 0
D32: b. | E32: Lainnya | H32: 10790 | I32: =ROUND(SUM(J32:X32),0) -> 0 | L32: 0 | M32: 0 | N32: 0 | O32: 0 | Q32: 0 | Y32: 1464+1466+1468
C33: 7. | D33: Lain-lain | H33: 10600 | I33: =ROUND(SUM(J33:X33),0) -> 15454 | J33: =(10041637.29+5412463.62)/1000 -> 15454.101 | Y33: 1075+1157+2468+2143+2153+2157+2253+2272+2281+2282+2401+2441+2451+2453+2462
J35: =J38-[4]SG!$J$38 -> 11934.748 | K35: =SUM(J40:L40)-SUM([4]SG!$J$40:$L$40) -> 48960.12
B36: B. | C36: Kewajiban | H36: 20000 | I36: =ROUND(SUM(J36:X36),0) -> 1856176 | J36: =ROUND(+J37+J44+J45+J46+J50+J53+J56,0) -> 231708 | K36: =ROUND(+K37+K44+K45+K46+K50+K53+K56,0) -> 159352 | L36: =ROUND(+L37+L44+L45+L46+L50+L53+L56,0) -> 158758 | M36: =ROUND(+M37+M44+M45+M46+M50+M53+M56,0) -> 244121 | N36: =ROUND(+N37+N44+N45+N46+N50+N53+N56,0) -> 359613 | O36: =ROUND(+O37+O44+O45+O46+O50+O53+O56,0) -> 107713 | P36: =ROUND(+P37+P44+P45+P46+P50+P53+P56,0) -> 109911 | Q36: =ROUND(+Q37+Q44+Q45+Q46+Q50+Q53+Q56,0) -> 0 | ... X36: =ROUND(+X37+X44+X45+X46+X50+X53+X56,0) -> 0
C37: 1. | D37: Dana Pihak Ketiga | H37: 20100 | I37: =ROUND(SUM(J37:X37),0) -> 368853 | J37: =+J38+J39+J40 -> 208177.52 | K37: =+K38+K39+K40 -> 31351.806 | L37: =+L38+L39+L40 -> 106757.56 | M37: =+M38+M39+M40 -> 18121.298 | N37: =+N38+N39+N40 -> 1732.0461 | O37: =+O38+O39+O40 -> 2713.0471 | P37: =+P38+P39+P40 -> 0 | Q37: =+Q38+Q39+Q40 -> 0 | ... X37: =+X38+X39+X40 -> 0
D38: a. | E38: Giro | H38: 20110 | I38: =ROUND(SUM(J38:X38),0) -> 184950 | J38: =(110353979.68+63118132.77+11478338.37)/1000 -> 184950.45 | Y38: 3011+3012+3013
D39: b. | E39: Tabungan | H39: 20120 | I39: =ROUND(SUM(J39:X39),0) -> 3121 | J39: =3121434.31/1000 -> 3121.4343 | Y39: 3101+3102
D40: c. | E40: Simpanan Berjangka | H40: 20130 | I40: =ROUND(SUM(J40:X40),0) -> 180781 | J40: =J41+J42+J43 -> 20105.635 | K40: =K41+K42+K43 -> 31351.806 | L40: =L41+L42+L43 -> 106757.56 | M40: =M41+M42+M43 -> 18121.298 | N40: =N41+N42+N43 -> 1732.0461 | O40: =O41+O42+O43 -> 2713.0471 | P40: 0 | Q40: 0 | R40: =+SUM(R41:R43) -> 0 | S40: =+SUM(S41:S43) -> 0 | T40: =+SUM(T41:T43) -> 0 | U40: =+SUM(U41:U43) -> 0 | V40: =+SUM(V41:V43) -> 0 | W40: =+SUM(W41:W43) -> 0 | X40: =+SUM(X41:X43) -> 0
E41: 1) | F41: Deposit on call | H41: 20131 | I41: =SUM(J41:M41) -> 0 | L41: 0
E42: 2) | F42: Deposito berjangka | H42: 20132 | I42: =ROUND(SUM(J42:X42),0) -> 180781 | J42: 20105.635 | K42: 31351.806 | L42: 106757.56 | M42: 18121.298 | N42: 1732.0461 | O42: 2713.0471
E43: 3) | F43: Lainnya | H43: 20139 | I43: =ROUND(SUM(J43:X43),0) -> 0 | J43: 0 | K43: 0 | L43: 0 | M43: 0 | N43: 0 | O43: 0 | P43: 0
C44: 2. | D44: Kewajiban kepada Bank Indonesia | H44: 20200 | I44: =ROUND(SUM(J44:X44),0) -> 0 | J44: 0 | K44: 0 | L44: 0 | M44: 0 | N44: 0 | O44: 0 | P44: 0
...

Sheet TKY
A2: A | B2: B | C2: C | D2: D | E2: E | F2: F | G2: G | I2: H | J2: I | K2: J | L2: K | M2: L | N2: M | O2: N
B3: Formulir 4.b.
B4: MATURITY PROFILE REPORT - BNI TOKYO Branch
B5: CONTRACTUAL BASED
B6: As of 30 June 2026
I7: Aset | J7: =(SUM(J14:L14))+(SUM(J62:L62)) -> 596768 | K7: =+J7/J8 -> 1.2518575 | L7: =J7-J8 -> 120062
I8: Kewajiban | J8: =(SUM(J36:L36))+(SUM(J71:L71))-((G89+G90+G91)/1000) -> 476706 | X8: in Thousand USD
J9: 46210 | K9: 46217 | L9: 46234 | M9: 46295 | N9: 46387 | O9: 46568 | P9: 46934 | Q9: 47299 | R9: 47664 | S9: 48029 | T9: 48760 | U9: 49856 | V9: 51682 | W9: 53508
B10: Pos-Pos | H10: Sandi | I10: Saldo | J10: Time to Maturity *)
J11: up to 1 week | K11: > 1 week to 2 weeks | L11: > 2 weeks to 1 month | M11: > 1 month to 3 months | N11: > 3 months to 6 months | O11: > 6 months to 1 year | P11: > 1 y to 2 y | Q11: > 2 y to 3 y | R11: > 3 y to 4 y | S11: > 4 y to 5 y | T11: > 5 y to 7 y | U11: > 7 y to 10 y | V11: > 10 y to 15 y | W11: > 15 y to 20 y | X11: > 20 y
B13: I. | C13: NERACA
B14: A. | C14: Aset | H14: 10000 | I14: 1021397 | J14: 505264 | K14: 0 | L14: 1504 | M14: 7810 | N14: 57021 | O14: 55616 | P14: 72615 | Q14: 169643 | R14: 16881 | S14: 10055 | T14: 44819 | U14: 77610 | V14: 2559 | W14: 0 | X14: 0
C15: 1. | D15: Kas | H15: 10100 | I15: 234 | J15: 233.93701 | K15: 0 | L15: 0 | M15: 0 | N15: 0 | O15: 0 | P15: 0 | Q15: 0 | R15: 0 | S15: 0 | T15: 0 | U15: 0 | V15: 0 | W15: 0 | X15: 0
C16: 2. | D16: Penempatan pada Bank Indonesia | H16: 10200 | I16: 0 | J16: 0 | K16: 0 | L16: 0 | M16: 0 | N16: 0 | O16: 0 | P16: 0 | Q16: 0 | R16: 0 | S16: 0 | T16: 0 | U16: 0 | V16: 0 | W16: 0 | X16: 0
C17: 3. | D17: Penempatan pada bank lain | H17: 10300 | I17: 505030 | J17: 505029.86 | K17: 0 | L17: 0 | M17: 0 | N17: 0 | O17: 0 | P17: 0 | Q17: 0 | R17: 0 | S17: 0 | T17: 0 | U17: 0 | V17: 0 | W17: 0 | X17: 0
E18: 1) | F18: Penempatan pada Bank Central setempat (BOJ) | I18: 390198.39 | J18: 390198.39
E19: 2) | F19: Penempatan pada bank lain exclude Bank Central | I19: 114831.47 | J19: 114831.47
C20: 4. | D20: Surat Berharga **) | H20: 10400 | I20: 116061 | K20: 0 | L20: 0 | M20: 0 | N20: 0 | O20: 41706.579 | P20: 19113.223 | Q20: 0 | R20: 16331.748 | S20: 9778.7724 | T20: 26571.795 | U20: 0 | V20: 2558.9009 | W20: 0 | X20: 0
D21: a. | E21: Surat berharga | H21: 10420 | I21: 116061 | J21: 0 | K21: 0 | L21: 0 | M21: 0 | N21: 0 | O21: 41706.579 | P21: 19113.223 | Q21: 0 | R21: 16331.748 | S21: 9778.7724 | T21: 26571.795 | U21: 0 | V21: 2558.9009 | W21: 0 | X21: 0
E22: 1) | F22: diperdagangkan | H22: 10421 | I22: 0 | J22: 0 | K22: 0 | L22: 0 | M22: 0 | N22: 0 | O22: 0 | P22: 0 | Q22: 0 | R22: 0 | S22: 0 | T22: 0 | U22: 0 | V22: 0 | W22: 0 | X22: 0
E23: 2) | F23: tersedia untuk dijual | H23: 10422 | I23: 78850 | J23: 0 | K23: 0 | L23: 0 | M23: 0 | N23: 0 | O23: 17540.225 | P23: 14046.013 | Q23: 0 | R23: 14357.925 | S23: 3775.2 | T23: 26571.795 | U23: 0 | V23: 2558.9009 | W23: 0 | X23: 0
E24: 3) | F24: dimiliki hingga jatuh tempo | H24: 10533 | I24: 37211 | J24: 0 | K24: 0 | L24: 0 | M24: 0 | N24: 0 | O24: 24166.354 | P24: 5067.2097 | Q24: 0 | R24: 1973.8231 | S24: 6003.5724 | T24: 0 | U24: 0 | V24: 0 | W24: 0 | X24: 0
E25: 4) | F25: pinjaman yang diberikan dan piutang | H25: 10424 | I25: 0 | J25: 0 | K25: 0 | L25: 0 | M25: 0 | N25: 0 | O25: 0 | P25: 0 | Q25: 0 | R25: 0 | S25: 0 | T25: 0 | U25: 0 | V25: 0 | W25: 0 | X25: 0
D26: b. | E26: Lainnya | H26: 10490 | I26: 0
C27: 5. | D27: Kredit Yang Diberikan | H27: 10500 | I27: 402770 | J27: 0 | K27: 0 | L27: 1503.587 | M27: 7809.6531 | N27: 57021.396 | O27: 13909.532 | P27: 56199.232 | Q27: 169643.28 | R27: 549.22735 | S27: 276.2386 | T27: 18247.468 | U27: 77609.955 | V27: 0 | W27: 0 | X27: 0
D28: a. | E28: belum jatuh tempo | H28: 10500 | I28: 402770 | J28: 0 | K28: 0 | L28: 1503.587 | M28: 7809.6531 | N28: 57021.396 | O28: 13909.532 | P28: 56199.232 | Q28: 169643.28 | R28: 549.22735 | S28: 276.2386 | T28: 18247.468 | U28: 77609.955 | V28: 0 | W28: 0 | X28: 0
D29: b. | E29: sudah jatuh tempo ***) | H29: 10520 | I29: 0
C30: 6. | D30: Tagihan lainnya | H30: 10700 | I30: 0 | J30: 0 | K30: 0 | L30: 0 | M30: 0 | N30: 0 | O30: 0 | P30: 0 | Q30: 0 | R30: 0 | S30: 0 | T30: 0 | U30: 0 | V30: 0 | W30: 0 | X30: 0
D31: a. | E31: Tagihan atas Surat Berharga yang dibeli dengan janji dijual kembali (Reverse Repo) | H31: 10710 | I31: 0 | J31: 0 | K31: 0 | L31: 0 | M31: 0 | N31: 0 | O31: 0 | P31: 0 | Q31: 0 | R31: 0 | S31: 0 | T31: 0 | U31: 0 | V31: 0 | W31: 0 | X31: 0
D32: b. | E32: Lainnya | H32: 10790 | I32: 0 | J32: 0 | K32: 0 | L32: 0 | M32: 0 | N32: 0 | O32: 0 | P32: 0 | Q32: 0 | R32: 0 | S32: 0 | T32: 0 | U32: 0 | V32: 0 | W32: 0 | X32: 0
C33: 7. | D33: Lain-lain | H33: 10600 | I33: -2698 | J33: 0 | K33: 0 | L33: 0 | M33: 0 | N33: 0 | O33: 0 | P33: -2697.6684 | Q33: 0 | R33: 0 | S33: 0 | T33: 0 | U33: 0 | V33: 0 | W33: 0 | X33: 0
J35: 46210 | K35: 46217 | L35: 46234 | M35: 46295 | N35: 46387 | O35: 46568 | P35: 46934
B36: B. | C36: Kewajiban | H36: 20000 | I36: 1021396 | J36: 467394 | K36: 0 | L36: 9312 | M36: 174203 | N36: 256175 | O36: 46329 | P36: 67982 | Q36: 0 | R36: 0 | S36: 0 | T36: 0 | U36: 0 | V36: 0 | W36: 0 | X36: 0
C37: 1. | D37: Dana Pihak Ketiga | H37: 20100 | I37: 497347 | J37: 461288.29 | K37: 0 | L37: 6224.7453 | M37: 11115.587 | N37: 0 | O37: 6369.1065 | P37: 12349.491 | Q37: 0 | R37: 0 | S37: 0 | T37: 0 | U37: 0 | V37: 0 | W37: 0 | X37: 0
D38: a. | E38: Giro | H38: 20110 | I38: 90253.11 | J38: 90253.11 | M38: 0 | N38: 0 | O38: 0 | P38: 0 | Q38: 0 | R38: 0 | S38: 0 | T38: 0 | U38: 0 | V38: 0 | W38: 0 | X38: 0
D39: b. | E39: Tabungan | H39: 20120 | I39: 371035.18 | J39: 371035.18 | K39: 0 | L39: 0 | M39: 0 | N39: 0 | O39: 0 | P39: 0 | Q39: 0 | R39: 0 | S39: 0 | T39: 0 | U39: 0 | V39: 0 | W39: 0 | X39: 0
D40: c. | E40: Simpanan Berjangka | H40: 20130 | I40: 36058.93 | J40: 0 | K40: 0 | L40: 6224.7453 | M40: 11115.587 | N40: 0 | O40: 6369.1065 | P40: 12349.491 | Q40: 0 | R40: 0 | S40: 0 | T40: 0 | U40: 0 | V40: 0 | W40: 0 | X40: 0
E41: 1) | F41: Deposit on call | H41: 20131 | I41: 0 | K41: 0 | L41: 0 | M41: 0 | N41: 0 | O41: 0 | Q41: 0 | R41: 0 | S41: 0 | T41: 0 | U41: 0 | V41: 0 | W41: 0 | X41: 0
E42: 2) | F42: Deposito berjangka | H42: 20132 | I42: 36058.93 | J42: 0 | K42: 0 | L42: 6224.7453 | M42: 11115.587 | N42: 0 | O42: 6369.1065 | P42: 12349.491 | Q42: 0 | R42: 0 | S42: 0 | T42: 0 | U42: 0 | V42: 0 | W42: 0
E43: 3) | F43: Lainnya | H43: 20139 | I43: 0 | J43: 0 | K43: 0 | L43: 0 | M43: 0 | N43: 0 | O43: 0 | P43: 0 | Q43: 0 | R43: 0 | S43: 0 | T43: 0 | U43: 0 | V43: 0 | W43: 0 | X43: 0
...
